Workbook

Sheet 페이백 포함
A1: 사업자 | B1: 요금제 | C1: 통화제공량 | D1: 문자제공량 | E1: 데이터 제공량 | F1: 망정보 | G1: LTE/5G 구분 | H1: 월 요금 | I1: 할인 기간 | J1: 기간 이후 요금 | K1: 요금구분
A2: LG U+ | B2: 너겟49 | C2: 무제한 | D2: 무제한 | E2: 월 120GB + 5Mbps | F2: LG U+ | G2: 5G | H2: 9000 | I2: 6 | J2: 41000 | K2: {=_xlfn.XLOOKUP(1,(참조!$B$2:$B$15=E2)*(참조!$D$2:$D$15=C2)*(참조!$E$2:$E$15=D2),참조!$C$2:$C$15,"")}
A3: U+유모바일 | B3: [평생할인] 5G 15GB+/300분 | C3: 300분 | D3: 300건 | E3: 월 15GB + 1Mbps | F3: LG U+ | G3: 5G | H3: 0 | I3: 7 | J3: 16900 | K3: {=_xlfn.XLOOKUP(1,(참조!$B$2:$B$15=E3)*(참조!$D$2:$D$15=C3)*(참조!$E$2:$E$15=D3),참조!$C$2:$C$15,"")}
A4: LG U+ | B4: 너겟49 | C4: 무제한 | D4: 무제한 | E4: 월 120GB + 5Mbps | F4: LG U+ | G4: 5G | H4: 9000 | I4: 6 | J4: 41000 | K4: {=_xlfn.XLOOKUP(1,(참조!$B$2:$B$15=E4)*(참조!$D$2:$D$15=C4)*(참조!$E$2:$E$15=D4),참조!$C$2:$C$15,"")}
A5: 찬스모바일 | B5: 5G 음성기본 125GB+5Mbps | C5: 무제한 | D5: 무제한 | E5: 월 125GB + 5Mbps | F5: LG U+ | G5: 5G | H5: 9800 | I5: 7 | J5: 55000 | K5: {=_xlfn.XLOOKUP(1,(참조!$B$2:$B$15=E5)*(참조!$D$2:$D$15=C5)*(참조!$E$2:$E$15=D5),참조!$C$2:$C$15,"")}
A6: 찬스모바일 | B6: 음성기본 맥스150GB+ | C6: 무제한 | D6: 무제한 | E6: 월 150GB + 5Mbps | F6: LG U+ | G6: 5G | H6: 10800 | I6: 7 | J6: 64900 | K6: {=_xlfn.XLOOKUP(1,(참조!$B$2:$B$15=E6)*(참조!$D$2:$D$15=C6)*(참조!$E$2:$E$15=D6),참조!$C$2:$C$15,"")}
A7: 핀다이렉트 | B7: [모요only] [K] 핀다이렉트Z 100GB+(네이버페이) _PAY | C7: 무제한 | D7: 무제한 | E7: 월 100GB + 5Mbps | F7: KT | G7: LTE | H7: 4000 | I7: 7 | J7: 43400 | K7: {=_xlfn.XLOOKUP(1,(참조!$B$2:$B$15=E7)*(참조!$D$2:$D$15=C7)*(참조!$E$2:$E$15=D7),참조!$C$2:$C$15,"")}
A8: LG U+ | B8: 데일리 너겟59 | C8: 무제한 | D8: 무제한 | E8: 무제한 | F8: LG U+ | G8: 5G | H8: 29000 | I8: 6 | J8: 34000 | K8: {=_xlfn.XLOOKUP(1,(참조!$B$2:$B$15=E8)*(참조!$D$2:$D$15=C8)*(참조!$E$2:$E$15=D8),참조!$C$2:$C$15,"")}
A9: U+유모바일 | B9: [평생할인] 15GB+/통화기본 | C9: 무제한 | D9: 무제한 | E9: 월 15GB + 1Mbps | F9: LG U+ | G9: LTE | H9: 0 | I9: 7 | J9: 20900 | K9: {=_xlfn.XLOOKUP(1,(참조!$B$2:$B$15=E9)*(참조!$D$2:$D$15=C9)*(참조!$E$2:$E$15=D9),참조!$C$2:$C$15,"")}
A10: 모나 | B10: 5G_코나아이데이터125G안심5 | C10: 무제한 | D10: 무제한 | E10: 월 125GB + 5Mbps | F10: LG U+ | G10: 5G | H10: 4400 | I10: 7 | J10: 57200 | K10: {=_xlfn.XLOOKUP(1,(참조!$B$2:$B$15=E10)*(참조!$D$2:$D$15=C10)*(참조!$E$2:$E$15=D10),참조!$C$2:$C$15,"")}
A11: 핀다이렉트 | B11: [모요only] [S] 핀다이렉트Z Max(네이버페이) _PAY | C11: 무제한 | D11: 무제한 | E11: 월 100GB + 5Mbps | F11: SKT | G11: LTE | H11: 4900 | I11: 7 | J11: 42900 | K11: {=_xlfn.XLOOKUP(1,(참조!$B$2:$B$15=E11)*(참조!$D$2:$D$15=C11)*(참조!$E$2:$E$15=D11),참조!$C$2:$C$15,"")}
A12: LG헬로모바일 | B12: 쿠폰팩 유심 11GB | C12: 무제한 | D12: 무제한 | E12: 월 11GB + 매일 2GB + 3Mbps | F12: LG U+ | G12: LTE | H12: 7730 | I12: 7 | J12: 30730 | K12: {=_xlfn.XLOOKUP(1,(참조!$B$2:$B$15=E12)*(참조!$D$2:$D$15=C12)*(참조!$E$2:$E$15=D12),참조!$C$2:$C$15,"")}
A13: 핀다이렉트 | B13: [모요only] [L] 핀다이렉트Z 100GB+(네이버페이) _PAY | C13: 무제한 | D13: 무제한 | E13: 월 100GB + 5Mbps | F13: LG U+ | G13: LTE | H13: 4900 | I13: 7 | J13: 44000 | K13: {=_xlfn.XLOOKUP(1,(참조!$B$2:$B$15=E13)*(참조!$D$2:$D$15=C13)*(참조!$E$2:$E$15=D13),참조!$C$2:$C$15,"")}
... A39: LG헬로모바일 | B39: 보편 안심 유심 15GB 300분 | C39: 300분 | D39: 300건 | E39: 월 15GB + 3Mbps | F39: LG U+ | G39: LTE | H39: 11900 | I39: 7 | J39: 31900 | K39: {=_xlfn.XLOOKUP(1,(참조!$B$2:$B$15=E39)*(참조!$D$2:$D$15=C39)*(참조!$E$2:$E$15=D39),참조!$C$2:$C$15,"")}
A40: KT스카이라이프 | B40: 슬림 1GB/100분 | C40: 100분 | D40: 100건 | E40: 월 1GB | F40: KT | G40: LTE | H40: 2900 | K40: {=_xlfn.XLOOKUP(1,(참조!$B$2:$B$15=E40)*(참조!$D$2:$D$15=C40)*(참조!$E$2:$E$15=D40),참조!$C$2:$C$15,"")}
A41: 더원모바일 | B41: TOP 7GB 기본 (네이버페이) | C41: 무제한 | D41: 무제한 | E41: 월 7GB + 1Mbps | F41: KT | G41: LTE | H41: 0 | I41: 7 | J41: 21400 | K41: {=_xlfn.XLOOKUP(1,(참조!$B$2:$B$15=E41)*(참조!$D$2:$D$15=C41)*(참조!$E$2:$E$15=D41),참조!$C$2:$C$15,"")}
A42: LG헬로모바일 | B42: 보편 안심 유심 15GB 180분 | C42: 180분 | D42: 100건 | E42: 월 15GB + 3Mbps | F42: LG U+ | G42: LTE | H42: 10800 | I42: 7 | J42: 30800 | K42: {=_xlfn.XLOOKUP(1,(참조!$B$2:$B$15=E42)*(참조!$D$2:$D$15=C42)*(참조!$E$2:$E$15=D42),참조!$C$2:$C$15,"")}
A43: 쉐이크모바일 | B43: [모요only] 쉐이크딜 LTE 100GB+_네이버페이(5,000) | C43: 무제한 | D43: 무제한 | E43: 월 100GB + 5Mbps | F43: KT | G43: LTE | H43: 4900 | I43: 7 | J43: 44500 | K43: {=_xlfn.XLOOKUP(1,(참조!$B$2:$B$15=E43)*(참조!$D$2:$D$15=C43)*(참조!$E$2:$E$15=D43),참조!$C$2:$C$15,"")}
A44: LG헬로모바일 | B44: DATA 걱정없는 유심 15GB | C44: 무제한 | D44: 무제한 | E44: 월 15GB + 1Mbps | F44: LG U+ | G44: LTE | H44: 9950 | I44: 7 | J44: 20950 | K44: {=_xlfn.XLOOKUP(1,(참조!$B$2:$B$15=E44)*(참조!$D$2:$D$15=C44)*(참조!$E$2:$E$15=D44),참조!$C$2:$C$15,"")}
A45: 고고모바일 | B45: [모요only] 고고딜 무제한 11GB+3M(Npay 5000P)_12개월 | C45: 무제한 | D45: 무제한 | E45: 월 11GB + 매일 2GB + 3Mbps | F45: KT | G45: LTE | H45: 17000 | I45: 12 | J45: 34600 | K45: {=_xlfn.XLOOKUP(1,(참조!$B$2:$B$15=E45)*(참조!$D$2:$D$15=C45)*(참조!$E$2:$E$15=D45),참조!$C$2:$C$15,"")}
A46: 고고모바일 | B46: [모요only] 고고딜 무제한 7GB+1M(Npay 5000P)_12개월 | C46: 무제한 | D46: 무제한 | E46: 월 7GB + 1Mbps | F46: KT | G46: LTE | H46: 5000 | I46: 12 | J46: 19200 | K46: {=_xlfn.XLOOKUP(1,(참조!$B$2:$B$15=E46)*(참조!$D$2:$D$15=C46)*(참조!$E$2:$E$15=D46),참조!$C$2:$C$15,"")}
A47: 쉐이크모바일 | B47: [모요only] 쉐이크 LTE 11GB+_네이버페이 매 월 5,000원 | C47: 무제한 | D47: 무제한 | E47: 월 11GB + 매일 2GB + 3Mbps | F47: KT | G47: LTE | H47: 4800 | I47: 7 | J47: 37900 | K47: {=_xlfn.XLOOKUP(1,(참조!$B$2:$B$15=E47)*(참조!$D$2:$D$15=C47)*(참조!$E$2:$E$15=D47),참조!$C$2:$C$15,"")}
A48: LG헬로모바일 | B48: 5G 유심 중간요금제 95GB | C48: 무제한 | D48: 무제한 | E48: 월 95GB + 3Mbps | F48: LG U+ | G48: 5G | H48: 24000 | I48: 7 | J48: 44000 | K48: {=_xlfn.XLOOKUP(1,(참조!$B$2:$B$15=E48)*(참조!$D$2:$D$15=C48)*(참조!$E$2:$E$15=D48),참조!$C$2:$C$15,"")}
A49: U+유모바일 | B49: 데이터 플러스 7GB(평생+10GB 추가 제공 프로모션) | C49: 무제한 | D49: 무제한 | E49: 월 17GB + 1Mbps | F49: LG U+ | G49: LTE | H49: 17500 | K49: {=_xlfn.XLOOKUP(1,(참조!$B$2:$B$15=E49)*(참조!$D$2:$D$15=C49)*(참조!$E$2:$E$15=D49),참조!$C$2:$C$15,"")}
A50: 쉐이크모바일 | B50: [모요only] 쉐이크 LTE 7GB+_네이버페이 매 월 5,000원 | C50: 무제한 | D50: 무제한 | E50: 월 7GB + 1Mbps | F50: KT | G50: LTE | H50: 0 | I50: 7 | J50: 34600 | K50: {=_xlfn.XLOOKUP(1,(참조!$B$2:$B$15=E50)*(참조!$D$2:$D$15=C50)*(참조!$E$2:$E$15=D50),참조!$C$2:$C$15,"")}
A51: LG헬로모바일 | B51: 보편 안심 유심 10GB 200분 | C51: 200분 | D51: 100건 | E51: 월 10GB + 1Mbps | F51: LG U+ | G51: LTE | H51: 7900 | I51: 7 | J51: 18900 | K51: {=_xlfn.XLOOKUP(1,(참조!$B$2:$B$15=E51)*(참조!$D$2:$D$15=C51)*(참조!$E$2:$E$15=D51),참조!$C$2:$C$15,"")}
A52: 더원모바일 | B52: TOP 11GB 기본 (네이버페이) | C52: 무제한 | D52: 무제한 | E52: 월 11GB + 매일 2GB + 3Mbps | F52: KT | G52: LTE | H52: 4900 | I52: 7 | J52: 35700 | K52: {=_xlfn.XLOOKUP(1,(참조!$B$2:$B$15=E52)*(참조!$D$2:$D$15=C52)*(참조!$E$2:$E$15=D52),참조!$C$2:$C$15,"")}
A53: 고고모바일 | B53: [모요only] 무제한 11GB+3M(매월 네이버페이5000P) | C53: 무제한 | D53: 무제한 | E53: 월 11GB + 매일 2GB + 3Mbps | F53: KT | G53: LTE | H53: 11000 | I53: 7 | J53: 35700 | K53: {=_xlfn.XLOOKUP(1,(참조!$B$2:$B$15=E53)*(참조!$D$2:$D$15=C53)*(참조!$E$2:$E$15=D53),참조!$C$2:$C$15,"")}
A54: 모나 | B54: 코나아이데이터11G+일2G | C54: 무제한 | D54: 무제한 | E54: 월 11GB + 매일 2GB + 3Mbps | F54: LG U+ | G54: LTE | H54: 27900 | K54: {=_xlfn.XLOOKUP(1,(참조!$B$2:$B$15=E54)*(참조!$D$2:$D$15=C54)*(참조!$E$2:$E$15=D54),참조!$C$2:$C$15,"")}
A55: 모나 | B55: 5G_모나알뜰125G안심5 | C55: 무제한 | D55: 무제한 | E55: 월 125GB + 5Mbps | F55: LG U+ | G55: 5G | H55: 27100 | I55: 24 | J55: 52200 | K55: {=_xlfn.XLOOKUP(1,(참조!$B$2:$B$15=E55)*(참조!$D$2:$D$15=C55)*(참조!$E$2:$E$15=D55),참조!$C$2:$C$15,"")}
A56: 모나 | B56: 코나아이데이터15G+(+10G)1M | C56: 무제한 | D56: 무제한 | E56: 월 25GB + 1Mbps | F56: LG U+ | G56: LTE | H56: 17990 | K56: {=_xlfn.XLOOKUP(1,(참조!$B$2:$B$15=E56)*(참조!$D$2:$D$15=C56)*(참조!$E$2:$E$15=D56),참조!$C$2:$C$15,"")}
A57: LG헬로모바일 | B57: 5G 유심 중간요금제 80GB | C57: 무제한 | D57: 무제한 | E57: 월 80GB + 1Mbps | F57: LG U+ | G57: 5G | H57: 22680 | I57: 7 | J57: 42680 | K57: {=_xlfn.XLOOKUP(1,(참조!$B$2:$B$15=E57)*(참조!$D$2:$D$15=C57)*(참조!$E$2:$E$15=D57),참조!$C$2:$C$15,"")}
A58: U+유모바일 | B58: [Npay 12만 기본제공] 7GB+/통화기본 | C58: 무제한 | D58: 무제한 | E58: 월 7GB + 1Mbps | F58: LG U+ | G58: LTE | H58: 13300 | I58: 24 | J58: 18300 | K58: {=_xlfn.XLOOKUP(1,(참조!$B$2:$B$15=E58)*(참조!$D$2:$D$15=C58)*(참조!$E$2:$E$15=D58),참조!$C$2:$C$15,"")}
A59: 모나 | B59: 코나아이데이터10G(+10G)+1M | C59: 무제한 | D59: 무제한 | E59: 월 20GB + 1Mbps | F59: LG U+ | G59: LTE | H59: 16990 | K59: {=_xlfn.XLOOKUP(1,(참조!$B$2:$B$15=E59)*(참조!$D$2:$D$15=C59)*(참조!$E$2:$E$15=D59),참조!$C$2:$C$15,"")}
A60: U+유모바일 | B60: [Npay 12만 기본제공] 17GB+/통화기본 | C60: 무제한 | D60: 무제한 | E60: 월 17GB + 1Mbps | F60: LG U+ | G60: LTE | H60: 14900 | I60: 24 | J60: 19900 | K60: {=_xlfn.XLOOKUP(1,(참조!$B$2:$B$15=E60)*(참조!$D$2:$D$15=C60)*(참조!$E$2:$E$15=D60),참조!$C$2:$C$15,"")}
A61: LG헬로모바일 | B61: 슬림 유심 2GB 200분 | C61: 200분 | D61: 150건 | E61: 월 2GB | F61: LG U+ | G61: LTE | H61: 0 | I61: 6 | J61: 3700 | K61: {=_xlfn.XLOOKUP(1,(참조!$B$2:$B$15=E61)*(참조!$D$2:$D$15=C61)*(참조!$E$2:$E$15=D61),참조!$C$2:$C$15,"")}
A62: LG헬로모바일 | B62: 5G 유심 중간요금제 31GB | C62: 무제한 | D62: 무제한 | E62: 월 31GB + 1Mbps | F62: LG U+ | G62: 5G | H62: 19600 | I62: 7 | J62: 39600 | K62: {=_xlfn.XLOOKUP(1,(참조!$B$2:$B$15=E62)*(참조!$D$2:$D$15=C62)*(참조!$E$2:$E$15=D62),참조!$C$2:$C$15,"")}
A63: 더원모바일 | B63: TOP 11GB 기본 (밀리의서재) | C63: 무제한 | D63: 무제한 | E63: 월 11GB + 매일 2GB + 3Mbps | F63: KT | G63: LTE | H63: 16500 | I63: 12 | J63: 38500 | K63: {=_xlfn.XLOOKUP(1,(참조!$B$2:$B$15=E63)*(참조!$D$2:$D$15=C63)*(참조!$E$2:$E$15=D63),참조!$C$2:$C$15,"")}
A64: LG헬로모바일 | B64: DATA 걱정없는 유심 1GB | C64: 무제한 | D64: 무제한 | E64: 월 1GB + 1Mbps | F64: LG U+ | G64: LTE | H64: 2500 | I64: 6 | J64: 7500 | K64: {=_xlfn.XLOOKUP(1,(참조!$B$2:$B$15=E64)*(참조!$D$2:$D$15=C64)*(참조!$E$2:$E$15=D64),참조!$C$2:$C$15,"")}
A65: KT엠모바일 | B65: 통화 맘껏 15GB | C65: 무제한 | D65: 무제한 | E65: 월 15GB | F65: KT | G65: LTE | H65: 12400 | K65: {=_xlfn.XLOOKUP(1,(참조!$B$2:$B$15=E65)*(참조!$D$2:$D$15=C65)*(참조!$E$2:$E$15=D65),참조!$C$2:$C$15,"")}
...

Sheet 페이백 미포함
A1: 사업자 | B1: 요금제 | C1: 통화제공량 | D1: 문자제공량 | E1: 데이터 제공량 | F1: 망정보 | G1: LTE/5G 구분 | H1: 월 요금 | I1: 할인 기간 | J1: 기간 이후 요금 | K1: 요금구분
A2: U+유모바일 | B2: [평생할인] 5G 15GB+/300분 | C2: 300분 | D2: 300건 | E2: 월 15GB + 1Mbps | F2: LG U+ | G2: 5G | H2: 16900 | K2: {=_xlfn.XLOOKUP(1,(참조!$B$2:$B$15=E2)*(참조!$D$2:$D$15=C2)*(참조!$E$2:$E$15=D2),참조!$C$2:$C$15,"")}
A3: 이지모바일 | B3: EG 무제한 100GB+5M(밀리의 서재) | C3: 무제한 | D3: 무제한 | E3: 월 100GB + 5Mbps | F3: KT | G3: LTE | H3: 6900 | I3: 6 | J3: 44000 | K3: {=_xlfn.XLOOKUP(1,(참조!$B$2:$B$15=E3)*(참조!$D$2:$D$15=C3)*(참조!$E$2:$E$15=D3),참조!$C$2:$C$15,"")}
A4: 인스모바일 | B4: 인스 유심 스피드(5G) 125GB+ | C4: 무제한 | D4: 무제한 | E4: 월 125GB + 5Mbps | F4: LG U+ | G4: 5G | H4: 4400 | I4: 7 | J4: 57090 | K4: {=_xlfn.XLOOKUP(1,(참조!$B$2:$B$15=E4)*(참조!$D$2:$D$15=C4)*(참조!$E$2:$E$15=D4),참조!$C$2:$C$15,"")}
A5: 마블링 | B5: [모요only] 마블링 프라임 11GB+매일2GB+3Mbps | C5: 무제한 | D5: 무제한 | E5: 월 11GB + 매일 2GB + 3Mbps | F5: LG U+ | G5: LTE | H5: 4500 | I5: 7 | J5: 38900 | K5: {=_xlfn.XLOOKUP(1,(참조!$B$2:$B$15=E5)*(참조!$D$2:$D$15=C5)*(참조!$E$2:$E$15=D5),참조!$C$2:$C$15,"")}
A6: 쉐이크모바일 | B6: [모요only] 쉐이크 5G 110GB+_네이버페이 매 월 5,000원 | C6: 무제한 | D6: 무제한 | E6: 월 110GB + 5Mbps | F6: KT | G6: 5G | H6: 9900 | I6: 7 | J6: 55000 | K6: {=_xlfn.XLOOKUP(1,(참조!$B$2:$B$15=E6)*(참조!$D$2:$D$15=C6)*(참조!$E$2:$E$15=D6),참조!$C$2:$C$15,"")}
A7: 인스모바일 | B7: 인스 유심 스트롱 11GB+ | C7: 무제한 | D7: 무제한 | E7: 월 11GB + 매일 2GB + 3Mbps | F7: LG U+ | G7: LTE | H7: 4490 | I7: 7 | J7: 39000 | K7: {=_xlfn.XLOOKUP(1,(참조!$B$2:$B$15=E7)*(참조!$D$2:$D$15=C7)*(참조!$E$2:$E$15=D7),참조!$C$2:$C$15,"")}
A8: 더원모바일 | B8: TOP 100GB 기본 (네이버페이) | C8: 무제한 | D8: 무제한 | E8: 월 100GB + 5Mbps | F8: KT | G8: LTE | H8: 22990 | I8: 12 | J8: 46200 | K8: {=_xlfn.XLOOKUP(1,(참조!$B$2:$B$15=E8)*(참조!$D$2:$D$15=C8)*(참조!$E$2:$E$15=D8),참조!$C$2:$C$15,"")}
A9: 쉐이크모바일 | B9: [모요only] 쉐이크 5G 110GB+_밀리의서재 | C9: 무제한 | D9: 무제한 | E9: 월 110GB + 5Mbps | F9: KT | G9: 5G | H9: 4900 | I9: 6 | J9: 48400 | K9: {=_xlfn.XLOOKUP(1,(참조!$B$2:$B$15=E9)*(참조!$D$2:$D$15=C9)*(참조!$E$2:$E$15=D9),참조!$C$2:$C$15,"")}
A10: 쉐이크모바일 | B10: [모요only] 쉐이크only LTE 100GB+밀리의서재 | C10: 무제한 | D10: 무제한 | E10: 월 100GB + 5Mbps | F10: KT | G10: LTE | H10: 7900 | I10: 7 | J10: 45100 | K10: {=_xlfn.XLOOKUP(1,(참조!$B$2:$B$15=E10)*(참조!$D$2:$D$15=C10)*(참조!$E$2:$E$15=D10),참조!$C$2:$C$15,"")}
A11: 모나 | B11: 모나210분4.5G | C11: 210분 | D11: 100건 | E11: 월 4.5GB | F11: LG U+ | G11: LTE | H11: 10 | I11: 18 | J11: 20900 | K11: {=_xlfn.XLOOKUP(1,(참조!$B$2:$B$15=E11)*(참조!$D$2:$D$15=C11)*(참조!$E$2:$E$15=D11),참조!$C$2:$C$15,"")}
A12: KG모바일 | B12: [일반] 데이터 마음대로 (4.5GB+/100분)_12개월 | C12: 100분 | D12: 100건 | E12: 월 4.5GB + 1Mbps | F12: LG U+ | G12: LTE | H12: 100 | I12: 12 | J12: 16800 | K12: {=_xlfn.XLOOKUP(1,(참조!$B$2:$B$15=E12)*(참조!$D$2:$D$15=C12)*(참조!$E$2:$E$15=D12),참조!$C$2:$C$15,"")}
A13: 찬스모바일 | B13: 음성기본 5GB+ | C13: 무제한 | D13: 무제한 | E13: 월 5GB + 1Mbps | F13: LG U+ | G13: LTE | H13: 10 | I13: 6 | J13: 16500 | K13: {=_xlfn.XLOOKUP(1,(참조!$B$2:$B$15=E13)*(참조!$D$2:$D$15=C13)*(참조!$E$2:$E$15=D13),참조!$C$2:$C$15,"")}
A14: 찬스모바일 | B14: 5G 음성기본 125GB+5Mbps | C14: 무제한 | D14: 무제한 | E14: 월 125GB + 5Mbps | F14: LG U+ | G14: 5G | H14: 7800 | I14: 7 | J14: 50600 | K14: {=_xlfn.XLOOKUP(1,(참조!$B$2:$B$15=E14)*(참조!$D$2:$D$15=C14)*(참조!$E$2:$E$15=D14),참조!$C$2:$C$15,"")}
... A26: 더원모바일 | B26: TOP 11GB 기본 (밀리의서재) | C26: 무제한 | D26: 무제한 | E26: 월 11GB + 매일 2GB + 3Mbps | F26: KT | G26: LTE | H26: 16500 | I26: 12 | J26: 38500 | K26: {=_xlfn.XLOOKUP(1,(참조!$B$2:$B$15=E26)*(참조!$D$2:$D$15=C26)*(참조!$E$2:$E$15=D26),참조!$C$2:$C$15,"")}
A27: KT스카이라이프 | B27: 슬림 1GB/100분 | C27: 100분 | D27: 100건 | E27: 월 1GB | F27: KT | G27: LTE | H27: 2900 | K27: {=_xlfn.XLOOKUP(1,(참조!$B$2:$B$15=E27)*(참조!$D$2:$D$15=C27)*(참조!$E$2:$E$15=D27),참조!$C$2:$C$15,"")}
A28: 모나 | B28: 5G_모나300분15G | C28: 300분 | D28: 300건 | E28: 월 15GB | F28: LG U+ | G28: 5G | H28: 10 | I28: 6 | J28: 36300 | K28: {=_xlfn.XLOOKUP(1,(참조!$B$2:$B$15=E28)*(참조!$D$2:$D$15=C28)*(참조!$E$2:$E$15=D28),참조!$C$2:$C$15,"")}
A29: 고고모바일 | B29: [모요only] 5G 200분/20GB | C29: 200분 | D29: 100건 | E29: 월 20GB | F29: KT | G29: 5G | H29: 100 | I29: 7 | J29: 29700 | K29: {=_xlfn.XLOOKUP(1,(참조!$B$2:$B$15=E29)*(참조!$D$2:$D$15=C29)*(참조!$E$2:$E$15=D29),참조!$C$2:$C$15,"")}
A30: LG헬로모바일 | B30: 슬림 유심 500MB 50분 | C30: 50분 | D30: 50건 | E30: 월 500MB | F30: LG U+ | G30: LTE | H30: 1700 | K30: {=_xlfn.XLOOKUP(1,(참조!$B$2:$B$15=E30)*(참조!$D$2:$D$15=C30)*(참조!$E$2:$E$15=D30),참조!$C$2:$C$15,"")}
A31: KG모바일 | B31: [일반] 통화, 데이터 마음대로 (5GB+) | C31: 무제한 | D31: 무제한 | E31: 월 5GB + 1Mbps | F31: LG U+ | G31: LTE | H31: 10 | I31: 6 | J31: 19300 | K31: {=_xlfn.XLOOKUP(1,(참조!$B$2:$B$15=E31)*(참조!$D$2:$D$15=C31)*(참조!$E$2:$E$15=D31),참조!$C$2:$C$15,"")}
A32: 더원모바일 | B32: TOP 11GB 기본 (밀리의서재) | C32: 무제한 | D32: 무제한 | E32: 월 11GB + 매일 2GB + 3Mbps | F32: KT | G32: LTE | H32: 7700 | I32: 7 | J32: 38500 | K32: {=_xlfn.XLOOKUP(1,(참조!$B$2:$B$15=E32)*(참조!$D$2:$D$15=C32)*(참조!$E$2:$E$15=D32),참조!$C$2:$C$15,"")}
A33: 이지모바일 | B33: 이지 데이터 7GB | C33: 300분 | D33: 100건 | E33: 월 7GB | F33: LG U+ | G33: LTE | H33: 10 | I33: 6 | J33: 17050 | K33: {=_xlfn.XLOOKUP(1,(참조!$B$2:$B$15=E33)*(참조!$D$2:$D$15=C33)*(참조!$E$2:$E$15=D33),참조!$C$2:$C$15,"")}
A34: 이지모바일 | B34: [선착순 특가]EG 7무제한 7G+1(매월10GB+밀리의 서재) | C34: 무제한 | D34: 무제한 | E34: 월 7GB + 1Mbps | F34: KT | G34: LTE | H34: 100 | I34: 7 | J34: 22000 | K34: {=_xlfn.XLOOKUP(1,(참조!$B$2:$B$15=E34)*(참조!$D$2:$D$15=C34)*(참조!$E$2:$E$15=D34),참조!$C$2:$C$15,"")}
A35: 더원모바일 | B35: TOP 100GB 기본 (밀리의서재) | C35: 무제한 | D35: 무제한 | E35: 월 100GB + 5Mbps | F35: KT | G35: LTE | H35: 20900 | I35: 12 | J35: 46200 | K35: {=_xlfn.XLOOKUP(1,(참조!$B$2:$B$15=E35)*(참조!$D$2:$D$15=C35)*(참조!$E$2:$E$15=D35),참조!$C$2:$C$15,"")}
A36: 모나 | B36: 모나400분4.5G | C36: 400분 | D36: 200건 | E36: 월 4.5GB | F36: LG U+ | G36: LTE | H36: 10 | I36: 12 | J36: 25300 | K36: {=_xlfn.XLOOKUP(1,(참조!$B$2:$B$15=E36)*(참조!$D$2:$D$15=C36)*(참조!$E$2:$E$15=D36),참조!$C$2:$C$15,"")}
A37: 티플러스 | B37: 가성비플러스(15GB/350분) | C37: 350분 | D37: 100건 | E37: 월 15GB | F37: KT | G37: LTE | H37: 10 | I37: 7 | J37: 22000 | K37: {=_xlfn.XLOOKUP(1,(참조!$B$2:$B$15=E37)*(참조!$D$2:$D$15=C37)*(참조!$E$2:$E$15=D37),참조!$C$2:$C$15,"")}
A38: 티플러스 | B38: 5G 가성비플러스(15GB/350분)_평생요금 | C38: 350분 | D38: 100건 | E38: 월 15GB | F38: KT | G38: 5G | H38: 7500 | K38: {=_xlfn.XLOOKUP(1,(참조!$B$2:$B$15=E38)*(참조!$D$2:$D$15=C38)*(참조!$E$2:$E$15=D38),참조!$C$2:$C$15,"")}
A39: 고고모바일 | B39: [모요only] 고고딜 무제한 100GB+5M(Npay 5000P)_12개월 | C39: 무제한 | D39: 무제한 | E39: 월 100GB + 5Mbps | F39: KT | G39: LTE | H39: 24000 | I39: 12 | J39: 48400 | K39: {=_xlfn.XLOOKUP(1,(참조!$B$2:$B$15=E39)*(참조!$D$2:$D$15=C39)*(참조!$E$2:$E$15=D39),참조!$C$2:$C$15,"")}
A40: 고고모바일 | B40: [모요only] 5G 200분/10GB | C40: 200분 | D40: 100건 | E40: 월 10GB | F40: KT | G40: 5G | H40: 10 | I40: 7 | J40: 18700 | K40: {=_xlfn.XLOOKUP(1,(참조!$B$2:$B$15=E40)*(참조!$D$2:$D$15=C40)*(참조!$E$2:$E$15=D40),참조!$C$2:$C$15,"")}
A41: 티플러스 | B41: KT 100GB+ (CU 매월 20%+올리브영 매월 5천원 상품권!) | C41: 무제한 | D41: 무제한 | E41: 월 100GB + 5Mbps | F41: KT | G41: LTE | H41: 8900 | I41: 7 | J41: 48400 | K41: {=_xlfn.XLOOKUP(1,(참조!$B$2:$B$15=E41)*(참조!$D$2:$D$15=C41)*(참조!$E$2:$E$15=D41),참조!$C$2:$C$15,"")}
A42: 핀다이렉트 | B42: [L] DIGITAL DETOX 7GB 챌린지 | C42: 100분 | D42: 100건 | E42: 월 7GB | F42: LG U+ | G42: LTE | H42: 10 | I42: 12 | J42: 17600 | K42: {=_xlfn.XLOOKUP(1,(참조!$B$2:$B$15=E42)*(참조!$D$2:$D$15=C42)*(참조!$E$2:$E$15=D42),참조!$C$2:$C$15,"")}
A43: 이지모바일 | B43: [5G]EG 무제한 110G+5 | C43: 무제한 | D43: 무제한 | E43: 월 110GB + 5Mbps | F43: KT | G43: 5G | H43: 9800 | I43: 6 | J43: 51700 | K43: {=_xlfn.XLOOKUP(1,(참조!$B$2:$B$15=E43)*(참조!$D$2:$D$15=C43)*(참조!$E$2:$E$15=D43),참조!$C$2:$C$15,"")}
A44: 찬스모바일 | B44: [5G] 100분5G | C44: 100분 | D44: 50건 | E44: 월 5GB | F44: LG U+ | G44: 5G | H44: 10 | I44: 6 | J44: 7700 | K44: {=_xlfn.XLOOKUP(1,(참조!$B$2:$B$15=E44)*(참조!$D$2:$D$15=C44)*(참조!$E$2:$E$15=D44),참조!$C$2:$C$15,"")}
A45: 고고모바일 | B45: [모요only] LTE 200분/ 10GB | C45: 200분 | D45: 100건 | E45: 월 10GB | F45: KT | G45: LTE | H45: 10 | I45: 7 | J45: 18480 | K45: {=_xlfn.XLOOKUP(1,(참조!$B$2:$B$15=E45)*(참조!$D$2:$D$15=C45)*(참조!$E$2:$E$15=D45),참조!$C$2:$C$15,"")}
A46: 이야기모바일 | B46: 요금걱정 제로 이야기 4.5GB+ | C46: 무제한 | D46: 무제한 | E46: 월 4.5GB + 1Mbps | F46: LG U+ | G46: LTE | H46: 990 | I46: 12 | J46: 9900 | K46: {=_xlfn.XLOOKUP(1,(참조!$B$2:$B$15=E46)*(참조!$D$2:$D$15=C46)*(참조!$E$2:$E$15=D46),참조!$C$2:$C$15,"")}
A47: 찬스모바일 | B47: [CHM] 음성 100분 6GB | C47: 100분 | D47: 100건 | E47: 월 6GB | F47: LG U+ | G47: LTE | H47: 10 | I47: 6 | J47: 3850 | K47: {=_xlfn.XLOOKUP(1,(참조!$B$2:$B$15=E47)*(참조!$D$2:$D$15=C47)*(참조!$E$2:$E$15=D47),참조!$C$2:$C$15,"")}
A48: 모나 | B48: 모나300분11G | C48: 300분 | D48: 200건 | E48: 월 11GB | F48: LG U+ | G48: LTE | H48: 10 | I48: 7 | J48: 33000 | K48: {=_xlfn.XLOOKUP(1,(참조!$B$2:$B$15=E48)*(참조!$D$2:$D$15=C48)*(참조!$E$2:$E$15=D48),참조!$C$2:$C$15,"")}
A49: 티플러스 | B49: 가성비플러스(6GB/350분)_평생요금 | C49: 350분 | D49: 100건 | E49: 월 6GB | F49: KT | G49: LTE | H49: 1900 | K49: {=_xlfn.XLOOKUP(1,(참조!$B$2:$B$15=E49)*(참조!$D$2:$D$15=C49)*(참조!$E$2:$E$15=D49),참조!$C$2:$C$15,"")}
A50: 티플러스 | B50: 가성비플러스(5GB/350분) | C50: 350분 | D50: 100건 | E50: 월 5GB | F50: KT | G50: LTE | H50: 10 | I50: 6 | J50: 8800 | K50: {=_xlfn.XLOOKUP(1,(참조!$B$2:$B$15=E50)*(참조!$D$2:$D$15=C50)*(참조!$E$2:$E$15=D50),참조!$C$2:$C$15,"")}
A51: 티플러스 | B51: 가성비플러스(10GB/350분) | C51: 350분 | D51: 100건 | E51: 월 10GB | F51: KT | G51: LTE | H51: 10 | I51: 7 | J51: 15400 | K51: {=_xlfn.XLOOKUP(1,(참조!$B$2:$B$15=E51)*(참조!$D$2:$D$15=C51)*(참조!$E$2:$E$15=D51),참조!$C$2:$C$15,"")}
...

Sheet 가이드 위반
B2: ■RS요금제 가이드 위반
B3: 순번 | C3: 사업자 | D3: 요금제 명 | E3: 월 요금 | F3: 할인 기간 | G3: 기간 이후 요금
B17: ■RM요금제 가이드 위반
B18: 순번 | C18: 사업자 | D18: 요금제 명 | E18: 월 요금 | F18: 할인 기간 | G18: 기간 이후 요금

Sheet 전일 대비 변동
A1: 변동구분 | B1: 사업자 | C1: 요금제 | D1: 망정보 | E1: LTE/5G | F1: 전일 월요금 | G1: 금일 월요금 | H1: 전일 할인기간 | I1: 금일 할인기간 | J1: 전일 이후요금 | K1: 금일 이후요금
A2: 삭제 | B2: LG헬로모바일 | C2: DATA 걱정없는 유심 1GB | D2: LG U+ | E2: LTE | F2: 7500 | H2: 7 | J2: 11550
A3: 신규 | B3: U+유모바일 | C3: [평생할인] 5G 15GB+/300분 | D3: LG U+ | E3: 5G | G3: 16900

Sheet 요약 및 통계
A1: 모요 요금제 요약 및 통계
A2: 생성시각 | B2: 2026-10-24 21:43:16
A3: 기준 | B3: 페이백 미포함
A5: 전체 저장 행 | B5: 1986
A6: RS | B6: 956
A7: RM | B7: 0
A8: 미분류 | B8: 1030
A9: RS 가이드 위반 | B9: 0
A10: RM 가이드 위반 | B10: 0
A12: LG U+망 | B12: 885
A13: KT망 | B13: 707
A14: SKT망 | B14: 394
A15: 망정보 미확인 | B15: 0
A16: LTE | B16: 1540
A17: 5G | B17: 446
... A23: 기타 변경 | B23: 0

Sheet 모요 판가
AA1: 사업자 최저가
B2: ■모요 채널 요금제 판가 비교 자료 | AA2: 요금제 최저가
B3: 사업자 | C3: 망 | D3: 7G | G3: 15GB + 100분 | J3: 15GB + 300분 | M3: 11G | P3: 100GB | S3: 95GB | V3: 125GB | Y3: 150GB
D4: 월 요금 | E4: 할인 기간 | F4: 기간 이후 요금 | G4: 월 요금 | H4: 할인 기간 | I4: 기간 이후 요금 | J4: 월 요금 | K4: 할인 기간 | L4: 기간 이후 요금 | M4: 월 요금 | N4: 할인 기간 | O4: 기간 이후 요금 | P4: 월 요금 | Q4: 할인 기간 | R4: 기간 이후 요금 | S4: 월 요금 | T4: 할인 기간 | U4: 기간 이후 요금 | V4: 월 요금 | W4: 할인 기간 | X4: 기간 이후 요금 | Y4: 월 요금 | Z4: 할인 기간 | AA4: 기간 이후 요금
B5: 프리티 | C5: SK | D5: {=_xlfn.LET(_xlpm.d,'페이백 미포함'!$A$2:$K$2061,_xlpm.p,_xlfn.XLOOKUP($B5,참조!$K$2:$K$30,IF(참조!$L$2:$L$30<>"",참조!$L$2:$L$30,참조!$M$2:$M$30),""),_xlpm.n,IF(OR($C5="SK",$C5="SKT"),"SKT",$C5),_xlpm.k,SUBSTITUTE(D$3,"GB","G"),_xlpm.s,_xlfn.XLOOKUP(_xlpm.k,참조!$F$2:$F$15,참조!$B$2:$B$15,""),_xlpm.v,_xlfn.XLOOKUP(_xlpm.k,참조!$F$2:$F$15,참조!$D$2:$D$15,""),_xlpm.t,_xlfn.XLOOKUP(_xlpm.k,참조!$F$2:$F$15,참조!$E$2:$E$15,""),_xlpm.x,_xlfn._xlws.FILTER(_xlpm.d,(INDEX(_xlpm.d,,1)=_xlpm.p)*(INDEX(_xlpm.d,,3)=_xlpm.v)*(INDEX(_xlpm.d,,4)=_xlpm.t)*(INDEX(_xlpm.d,,5)=_xlpm.s)*(INDEX(_xlpm.d,,6)=_xlpm.n)*(INDEX(_xlpm.d,,11)="RS")),_xlpm.y,_xlfn.SORTBY(_xlpm.x,INDEX(_xlpm.x,,8),1,IF(INDEX(_xlpm.x,,9)="",1E+99,INDEX(_xlpm.x,,9)),-1,IF(INDEX(_xlpm.x,,10)="",0,INDEX(_xlpm.x,,10)),1),IFERROR(_xlfn.CHOOSECOLS(_xlfn.TAKE(_xlpm.y,1),8,9,10),""))} | G5: {=_xlfn.LET(_xlpm.d,'페이백 미포함'!$A$2:$K$2061,_xlpm.p,_xlfn.XLOOKUP($B5,참조!$K$2:$K$30,IF(참조!$L$2:$L$30<>"",참조!$L$2:$L$30,참조!$M$2:$M$30),""),_xlpm.n,IF(OR($C5="SK",$C5="SKT"),"SKT",$C5),_xlpm.k,SUBSTITUTE(G$3,"GB","G"),_xlpm.s,_xlfn.XLOOKUP(_xlpm.k,참조!$F$2:$F$15,참조!$B$2:$B$15,""),_xlpm.v,_xlfn.XLOOKUP(_xlpm.k,참조!$F$2:$F$15,참조!$D$2:$D$15,""),_xlpm.t,_xlfn.XLOOKUP(_xlpm.k,참조!$F$2:$F$15,참조!$E$2:$E$15,""),_xlpm.x,_xlfn._xlws.FILTER(_xlpm.d,(INDEX(_xlpm.d,,1)=_xlpm.p)*(INDEX(_xlpm.d,,3)=_xlpm.v)*(INDEX(_xlpm.d,,4)=_xlpm.t)*(INDEX(_xlpm.d,,5)=_xlpm.s)*(INDEX(_xlpm.d,,6)=_xlpm.n)*(INDEX(_xlpm.d,,11)="RS")),_xlpm.y,_xlfn.SORTBY(_xlpm.x,INDEX(_xlpm.x,,8),1,IF(INDEX(_xlpm.x,,9)="",1E+99,INDEX(_xlpm.x,,9)),-1,IF(INDEX(_xlpm.x,,10)="",0,INDEX(_xlpm.x,,10)),1),IFERROR(_xlfn.CHOOSECOLS(_xlfn.TAKE(_xlpm.y,1),8,9,10),""))} | H5: 12 | I5: 30800 | J5: {=_xlfn.LET(_xlpm.d,'페이백 미포함'!$A$2:$K$2061,_xlpm.p,_xlfn.XLOOKUP($B5,참조!$K$2:$K$30,IF(참조!$L$2:$L$30<>"",참조!$L$2:$L$30,참조!$M$2:$M$30),""),_xlpm.n,IF(OR($C5="SK",$C5="SKT"),"SKT",$C5),_xlpm.k,SUBSTITUTE(J$3,"GB","G"),_xlpm.s,_xlfn.XLOOKUP(_xlpm.k,참조!$F$2:$F$15,참조!$B$2:$B$15,""),_xlpm.v,_xlfn.XLOOKUP(_xlpm.k,참조!$F$2:$F$15,참조!$D$2:$D$15,""),_xlpm.t,_xlfn.XLOOKUP(_xlpm.k,참조!$F$2:$F$15,참조!$E$2:$E$15,""),_xlpm.x,_xlfn._xlws.FILTER(_xlpm.d,(INDEX(_xlpm.d,,1)=_xlpm.p)*(INDEX(_xlpm.d,,3)=_xlpm.v)*(INDEX(_xlpm.d,,4)=_xlpm.t)*(INDEX(_xlpm.d,,5)=_xlpm.s)*(INDEX(_xlpm.d,,6)=_xlpm.n)*(INDEX(_xlpm.d,,11)="RS")),_xlpm.y,_xlfn.SORTBY(_xlpm.x,INDEX(_xlpm.x,,8),1,IF(INDEX(_xlpm.x,,9)="",1E+99,INDEX(_xlpm.x,,9)),-1,IF(INDEX(_xlpm.x,,10)="",0,INDEX(_xlpm.x,,10)),1),IFERROR(_xlfn.CHOOSECOLS(_xlfn.TAKE(_xlpm.y,1),8,9,10),""))} | M5: {=_xlfn.LET(_xlpm.d,'페이백 미포함'!$A$2:$K$2061,_xlpm.p,_xlfn.XLOOKUP($B5,참조!$K$2:$K$30,IF(참조!$L$2:$L$30<>"",참조!$L$2:$L$30,참조!$M$2:$M$30),""),_xlpm.n,IF(OR($C5="SK",$C5="SKT"),"SKT",$C5),_xlpm.k,SUBSTITUTE(M$3,"GB","G"),_xlpm.s,_xlfn.XLOOKUP(_xlpm.k,참조!$F$2:$F$15,참조!$B$2:$B$15,""),_xlpm.v,_xlfn.XLOOKUP(_xlpm.k,참조!$F$2:$F$15,참조!$D$2:$D$15,""),_xlpm.t,_xlfn.XLOOKUP(_xlpm.k,참조!$F$2:$F$15,참조!$E$2:$E$15,""),_xlpm.x,_xlfn._xlws.FILTER(_xlpm.d,(INDEX(_xlpm.d,,1)=_xlpm.p)*(INDEX(_xlpm.d,,3)=_xlpm.v)*(INDEX(_xlpm.d,,4)=_xlpm.t)*(INDEX(_xlpm.d,,5)=_xlpm.s)*(INDEX(_xlpm.d,,6)=_xlpm.n)*(INDEX(_xlpm.d,,11)="RS")),_xlpm.y,_xlfn.SORTBY(_xlpm.x,INDEX(_xlpm.x,,8),1,IF(INDEX(_xlpm.x,,9)="",1E+99,INDEX(_xlpm.x,,9)),-1,IF(INDEX(_xlpm.x,,10)="",0,INDEX(_xlpm.x,,10)),1),IFERROR(_xlfn.CHOOSECOLS(_xlfn.TAKE(_xlpm.y,1),8,9,10),""))} | P5: {=_xlfn.LET(_xlpm.d,'페이백 미포함'!$A$2:$K$2061,_xlpm.p,_xlfn.XLOOKUP($B5,참조!$K$2:$K$30,IF(참조!$L$2:$L$30<>"",참조!$L$2:$L$30,참조!$M$2:$M$30),""),_xlpm.n,IF(OR($C5="SK",$C5="SKT"),"SKT",$C5),_xlpm.k,SUBSTITUTE(P$3,"GB","G"),_xlpm.s,_xlfn.XLOOKUP(_xlpm.k,참조!$F$2:$F$15,참조!$B$2:$B$15,""),_xlpm.v,_xlfn.XLOOKUP(_xlpm.k,참조!$F$2:$F$15,참조!$D$2:$D$15,""),_xlpm.t,_xlfn.XLOOKUP(_xlpm.k,참조!$F$2:$F$15,참조!$E$2:$E$15,""),_xlpm.x,_xlfn._xlws.FILTER(_xlpm.d,(INDEX(_xlpm.d,,1)=_xlpm.p)*(INDEX(_xlpm.d,,3)=_xlpm.v)*(INDEX(_xlpm.d,,4)=_xlpm.t)*(INDEX(_xlpm.d,,5)=_xlpm.s)*(INDEX(_xlpm.d,,6)=_xlpm.n)*(INDEX(_xlpm.d,,11)="RS")),_xlpm.y,_xlfn.SORTBY(_xlpm.x,INDEX(_xlpm.x,,8),1,IF(INDEX(_xlpm.x,,9)="",1E+99,INDEX(_xlpm.x,,9)),-1,IF(INDEX(_xlpm.x,,10)="",0,INDEX(_xlpm.x,,10)),1),IFERROR(_xlfn.CHOOSECOLS(_xlfn.TAKE(_xlpm.y,1),8,9,10),""))} | S5: {=_xlfn.LET(_xlpm.d,'페이백 미포함'!$A$2:$K$2061,_xlpm.p,_xlfn.XLOOKUP($B5,참조!$K$2:$K$30,IF(참조!$L$2:$L$30<>"",참조!$L$2:$L$30,참조!$M$2:$M$30),""),_xlpm.n,IF(OR($C5="SK",$C5="SKT"),"SKT",$C5),_xlpm.k,SUBSTITUTE(S$3,"GB","G"),_xlpm.s,_xlfn.XLOOKUP(_xlpm.k,참조!$F$2:$F$15,참조!$B$2:$B$15,""),_xlpm.v,_xlfn.XLOOKUP(_xlpm.k,참조!$F$2:$F$15,참조!$D$2:$D$15,""),_xlpm.t,_xlfn.XLOOKUP(_xlpm.k,참조!$F$2:$F$15,참조!$E$2:$E$15,""),_xlpm.x,_xlfn._xlws.FILTER(_xlpm.d,(INDEX(_xlpm.d,,1)=_xlpm.p)*(INDEX(_xlpm.d,,3)=_xlpm.v)*(INDEX(_xlpm.d,,4)=_xlpm.t)*(INDEX(_xlpm.d,,5)=_xlpm.s)*(INDEX(_xlpm.d,,6)=_xlpm.n)*(INDEX(_xlpm.d,,11)="RS")),_xlpm.y,_xlfn.SORTBY(_xlpm.x,INDEX(_xlpm.x,,8),1,IF(INDEX(_xlpm.x,,9)="",1E+99,INDEX(_xlpm.x,,9)),-1,IF(INDEX(_xlpm.x,,10)="",0,INDEX(_xlpm.x,,10)),1),IFERROR(_xlfn.CHOOSECOLS(_xlfn.TAKE(_xlpm.y,1),8,9,10),""))} | V5: {=_xlfn.LET(_xlpm.d,'페이백 미포함'!$A$2:$K$2061,_xlpm.p,_xlfn.XLOOKUP($B5,참조!$K$2:$K$30,IF(참조!$L$2:$L$30<>"",참조!$L$2:$L$30,참조!$M$2:$M$30),""),_xlpm.n,IF(OR($C5="SK",$C5="SKT"),"SKT",$C5),_xlpm.k,SUBSTITUTE(V$3,"GB","G"),_xlpm.s,_xlfn.XLOOKUP(_xlpm.k,참조!$F$2:$F$15,참조!$B$2:$B$15,""),_xlpm.v,_xlfn.XLOOKUP(_xlpm.k,참조!$F$2:$F$15,참조!$D$2:$D$15,""),_xlpm.t,_xlfn.XLOOKUP(_xlpm.k,참조!$F$2:$F$15,참조!$E$2:$E$15,""),_xlpm.x,_xlfn._xlws.FILTER(_xlpm.d,(INDEX(_xlpm.d,,1)=_xlpm.p)*(INDEX(_xlpm.d,,3)=_xlpm.v)*(INDEX(_xlpm.d,,4)=_xlpm.t)*(INDEX(_xlpm.d,,5)=_xlpm.s)*(INDEX(_xlpm.d,,6)=_xlpm.n)*(INDEX(_xlpm.d,,11)="RS")),_xlpm.y,_xlfn.SORTBY(_xlpm.x,INDEX(_xlpm.x,,8),1,IF(INDEX(_xlpm.x,,9)="",1E+99,INDEX(_xlpm.x,,9)),-1,IF(INDEX(_xlpm.x,,10)="",0,INDEX(_xlpm.x,,10)),1),IFERROR(_xlfn.CHOOSECOLS(_xlfn.TAKE(_xlpm.y,1),8,9,10),""))} | Y5: {=_xlfn.LET(_xlpm.d,'페이백 미포함'!$A$2:$K$2061,_xlpm.p,_xlfn.XLOOKUP($B5,참조!$K$2:$K$30,IF(참조!$L$2:$L$30<>"",참조!$L$2:$L$30,참조!$M$2:$M$30),""),_xlpm.n,IF(OR($C5="SK",$C5="SKT"),"SKT",$C5),_xlpm.k,SUBSTITUTE(Y$3,"GB","G"),_xlpm.s,_xlfn.XLOOKUP(_xlpm.k,참조!$F$2:$F$15,참조!$B$2:$B$15,""),_xlpm.v,_xlfn.XLOOKUP(_xlpm.k,참조!$F$2:$F$15,참조!$D$2:$D$15,""),_xlpm.t,_xlfn.XLOOKUP(_xlpm.k,참조!$F$2:$F$15,참조!$E$2:$E$15,""),_xlpm.x,_xlfn._xlws.FILTER(_xlpm.d,(INDEX(_xlpm.d,,1)=_xlpm.p)*(INDEX(_xlpm.d,,3)=_xlpm.v)*(INDEX(_xlpm.d,,4)=_xlpm.t)*(INDEX(_xlpm.d,,5)=_xlpm.s)*(INDEX(_xlpm.d,,6)=_xlpm.n)*(INDEX(_xlpm.d,,11)="RS")),_xlpm.y,_xlfn.SORTBY(_xlpm.x,INDEX(_xlpm.x,,8),1,IF(INDEX(_xlpm.x,,9)="",1E+99,INDEX(_xlpm.x,,9)),-1,IF(INDEX(_xlpm.x,,10)="",0,INDEX(_xlpm.x,,10)),1),IFERROR(_xlfn.CHOOSECOLS(_xlfn.TAKE(_xlpm.y,1),8,9,10),""))}
B6: =B5 | C6: KT | D6: {=_xlfn.LET(_xlpm.d,'페이백 미포함'!$A$2:$K$2061,_xlpm.p,_xlfn.XLOOKUP($B6,참조!$K$2:$K$30,IF(참조!$L$2:$L$30<>"",참조!$L$2:$L$30,참조!$M$2:$M$30),""),_xlpm.n,IF(OR($C6="SK",$C6="SKT"),"SKT",$C6),_xlpm.k,SUBSTITUTE(D$3,"GB","G"),_xlpm.s,_xlfn.XLOOKUP(_xlpm.k,참조!$F$2:$F$15,참조!$B$2:$B$15,""),_xlpm.v,_xlfn.XLOOKUP(_xlpm.k,참조!$F$2:$F$15,참조!$D$2:$D$15,""),_xlpm.t,_xlfn.XLOOKUP(_xlpm.k,참조!$F$2:$F$15,참조!$E$2:$E$15,""),_xlpm.x,_xlfn._xlws.FILTER(_xlpm.d,(INDEX(_xlpm.d,,1)=_xlpm.p)*(INDEX(_xlpm.d,,3)=_xlpm.v)*(INDEX(_xlpm.d,,4)=_xlpm.t)*(INDEX(_xlpm.d,,5)=_xlpm.s)*(INDEX(_xlpm.d,,6)=_xlpm.n)*(INDEX(_xlpm.d,,11)="RS")),_xlpm.y,_xlfn.SORTBY(_xlpm.x,INDEX(_xlpm.x,,8),1,IF(INDEX(_xlpm.x,,9)="",1E+99,INDEX(_xlpm.x,,9)),-1,IF(INDEX(_xlpm.x,,10)="",0,INDEX(_xlpm.x,,10)),1),IFERROR(_xlfn.CHOOSECOLS(_xlfn.TAKE(_xlpm.y,1),8,9,10),""))} | G6: {=_xlfn.LET(_xlpm.d,'페이백 미포함'!$A$2:$K$2061,_xlpm.p,_xlfn.XLOOKUP($B6,참조!$K$2:$K$30,IF(참조!$L$2:$L$30<>"",참조!$L$2:$L$30,참조!$M$2:$M$30),""),_xlpm.n,IF(OR($C6="SK",$C6="SKT"),"SKT",$C6),_xlpm.k,SUBSTITUTE(G$3,"GB","G"),_xlpm.s,_xlfn.XLOOKUP(_xlpm.k,참조!$F$2:$F$15,참조!$B$2:$B$15,""),_xlpm.v,_xlfn.XLOOKUP(_xlpm.k,참조!$F$2:$F$15,참조!$D$2:$D$15,""),_xlpm.t,_xlfn.XLOOKUP(_xlpm.k,참조!$F$2:$F$15,참조!$E$2:$E$15,""),_xlpm.x,_xlfn._xlws.FILTER(_xlpm.d,(INDEX(_xlpm.d,,1)=_xlpm.p)*(INDEX(_xlpm.d,,3)=_xlpm.v)*(INDEX(_xlpm.d,,4)=_xlpm.t)*(INDEX(_xlpm.d,,5)=_xlpm.s)*(INDEX(_xlpm.d,,6)=_xlpm.n)*(INDEX(_xlpm.d,,11)="RS")),_xlpm.y,_xlfn.SORTBY(_xlpm.x,INDEX(_xlpm.x,,8),1,IF(INDEX(_xlpm.x,,9)="",1E+99,INDEX(_xlpm.x,,9)),-1,IF(INDEX(_xlpm.x,,10)="",0,INDEX(_xlpm.x,,10)),1),IFERROR(_xlfn.CHOOSECOLS(_xlfn.TAKE(_xlpm.y,1),8,9,10),""))} | H6: 7 | I6: 33000 | J6: {=_xlfn.LET(_xlpm.d,'페이백 미포함'!$A$2:$K$2061,_xlpm.p,_xlfn.XLOOKUP($B6,참조!$K$2:$K$30,IF(참조!$L$2:$L$30<>"",참조!$L$2:$L$30,참조!$M$2:$M$30),""),_xlpm.n,IF(OR($C6="SK",$C6="SKT"),"SKT",$C6),_xlpm.k,SUBSTITUTE(J$3,"GB","G"),_xlpm.s,_xlfn.XLOOKUP(_xlpm.k,참조!$F$2:$F$15,참조!$B$2:$B$15,""),_xlpm.v,_xlfn.XLOOKUP(_xlpm.k,참조!$F$2:$F$15,참조!$D$2:$D$15,""),_xlpm.t,_xlfn.XLOOKUP(_xlpm.k,참조!$F$2:$F$15,참조!$E$2:$E$15,""),_xlpm.x,_xlfn._xlws.FILTER(_xlpm.d,(INDEX(_xlpm.d,,1)=_xlpm.p)*(INDEX(_xlpm.d,,3)=_xlpm.v)*(INDEX(_xlpm.d,,4)=_xlpm.t)*(INDEX(_xlpm.d,,5)=_xlpm.s)*(INDEX(_xlpm.d,,6)=_xlpm.n)*(INDEX(_xlpm.d,,11)="RS")),_xlpm.y,_xlfn.SORTBY(_xlpm.x,INDEX(_xlpm.x,,8),1,IF(INDEX(_xlpm.x,,9)="",1E+99,INDEX(_xlpm.x,,9)),-1,IF(INDEX(_xlpm.x,,10)="",0,INDEX(_xlpm.x,,10)),1),IFERROR(_xlfn.CHOOSECOLS(_xlfn.TAKE(_xlpm.y,1),8,9,10),""))} | M6: {=_xlfn.LET(_xlpm.d,'페이백 미포함'!$A$2:$K$2061,_xlpm.p,_xlfn.XLOOKUP($B6,참조!$K$2:$K$30,IF(참조!$L$2:$L$30<>"",참조!$L$2:$L$30,참조!$M$2:$M$30),""),_xlpm.n,IF(OR($C6="SK",$C6="SKT"),"SKT",$C6),_xlpm.k,SUBSTITUTE(M$3,"GB","G"),_xlpm.s,_xlfn.XLOOKUP(_xlpm.k,참조!$F$2:$F$15,참조!$B$2:$B$15,""),_xlpm.v,_xlfn.XLOOKUP(_xlpm.k,참조!$F$2:$F$15,참조!$D$2:$D$15,""),_xlpm.t,_xlfn.XLOOKUP(_xlpm.k,참조!$F$2:$F$15,참조!$E$2:$E$15,""),_xlpm.x,_xlfn._xlws.FILTER(_xlpm.d,(INDEX(_xlpm.d,,1)=_xlpm.p)*(INDEX(_xlpm.d,,3)=_xlpm.v)*(INDEX(_xlpm.d,,4)=_xlpm.t)*(INDEX(_xlpm.d,,5)=_xlpm.s)*(INDEX(_xlpm.d,,6)=_xlpm.n)*(INDEX(_xlpm.d,,11)="RS")),_xlpm.y,_xlfn.SORTBY(_xlpm.x,INDEX(_xlpm.x,,8),1,IF(INDEX(_xlpm.x,,9)="",1E+99,INDEX(_xlpm.x,,9)),-1,IF(INDEX(_xlpm.x,,10)="",0,INDEX(_xlpm.x,,10)),1),IFERROR(_xlfn.CHOOSECOLS(_xlfn.TAKE(_xlpm.y,1),8,9,10),""))} | P6: {=_xlfn.LET(_xlpm.d,'페이백 미포함'!$A$2:$K$2061,_xlpm.p,_xlfn.XLOOKUP($B6,참조!$K$2:$K$30,IF(참조!$L$2:$L$30<>"",참조!$L$2:$L$30,참조!$M$2:$M$30),""),_xlpm.n,IF(OR($C6="SK",$C6="SKT"),"SKT",$C6),_xlpm.k,SUBSTITUTE(P$3,"GB","G"),_xlpm.s,_xlfn.XLOOKUP(_xlpm.k,참조!$F$2:$F$15,참조!$B$2:$B$15,""),_xlpm.v,_xlfn.XLOOKUP(_xlpm.k,참조!$F$2:$F$15,참조!$D$2:$D$15,""),_xlpm.t,_xlfn.XLOOKUP(_xlpm.k,참조!$F$2:$F$15,참조!$E$2:$E$15,""),_xlpm.x,_xlfn._xlws.FILTER(_xlpm.d,(INDEX(_xlpm.d,,1)=_xlpm.p)*(INDEX(_xlpm.d,,3)=_xlpm.v)*(INDEX(_xlpm.d,,4)=_xlpm.t)*(INDEX(_xlpm.d,,5)=_xlpm.s)*(INDEX(_xlpm.d,,6)=_xlpm.n)*(INDEX(_xlpm.d,,11)="RS")),_xlpm.y,_xlfn.SORTBY(_xlpm.x,INDEX(_xlpm.x,,8),1,IF(INDEX(_xlpm.x,,9)="",1E+99,INDEX(_xlpm.x,,9)),-1,IF(INDEX(_xlpm.x,,10)="",0,INDEX(_xlpm.x,,10)),1),IFERROR(_xlfn.CHOOSECOLS(_xlfn.TAKE(_xlpm.y,1),8,9,10),""))} | S6: {=_xlfn.LET(_xlpm.d,'페이백 미포함'!$A$2:$K$2061,_xlpm.p,_xlfn.XLOOKUP($B6,참조!$K$2:$K$30,IF(참조!$L$2:$L$30<>"",참조!$L$2:$L$30,참조!$M$2:$M$30),""),_xlpm.n,IF(OR($C6="SK",$C6="SKT"),"SKT",$C6),_xlpm.k,SUBSTITUTE(S$3,"GB","G"),_xlpm.s,_xlfn.XLOOKUP(_xlpm.k,참조!$F$2:$F$15,참조!$B$2:$B$15,""),_xlpm.v,_xlfn.XLOOKUP(_xlpm.k,참조!$F$2:$F$15,참조!$D$2:$D$15,""),_xlpm.t,_xlfn.XLOOKUP(_xlpm.k,참조!$F$2:$F$15,참조!$E$2:$E$15,""),_xlpm.x,_xlfn._xlws.FILTER(_xlpm.d,(INDEX(_xlpm.d,,1)=_xlpm.p)*(INDEX(_xlpm.d,,3)=_xlpm.v)*(INDEX(_xlpm.d,,4)=_xlpm.t)*(INDEX(_xlpm.d,,5)=_xlpm.s)*(INDEX(_xlpm.d,,6)=_xlpm.n)*(INDEX(_xlpm.d,,11)="RS")),_xlpm.y,_xlfn.SORTBY(_xlpm.x,INDEX(_xlpm.x,,8),1,IF(INDEX(_xlpm.x,,9)="",1E+99,INDEX(_xlpm.x,,9)),-1,IF(INDEX(_xlpm.x,,10)="",0,INDEX(_xlpm.x,,10)),1),IFERROR(_xlfn.CHOOSECOLS(_xlfn.TAKE(_xlpm.y,1),8,9,10),""))} | V6: {=_xlfn.LET(_xlpm.d,'페이백 미포함'!$A$2:$K$2061,_xlpm.p,_xlfn.XLOOKUP($B6,참조!$K$2:$K$30,IF(참조!$L$2:$L$30<>"",참조!$L$2:$L$30,참조!$M$2:$M$30),""),_xlpm.n,IF(OR($C6="SK",$C6="SKT"),"SKT",$C6),_xlpm.k,SUBSTITUTE(V$3,"GB","G"),_xlpm.s,_xlfn.XLOOKUP(_xlpm.k,참조!$F$2:$F$15,참조!$B$2:$B$15,""),_xlpm.v,_xlfn.XLOOKUP(_xlpm.k,참조!$F$2:$F$15,참조!$D$2:$D$15,""),_xlpm.t,_xlfn.XLOOKUP(_xlpm.k,참조!$F$2:$F$15,참조!$E$2:$E$15,""),_xlpm.x,_xlfn._xlws.FILTER(_xlpm.d,(INDEX(_xlpm.d,,1)=_xlpm.p)*(INDEX(_xlpm.d,,3)=_xlpm.v)*(INDEX(_xlpm.d,,4)=_xlpm.t)*(INDEX(_xlpm.d,,5)=_xlpm.s)*(INDEX(_xlpm.d,,6)=_xlpm.n)*(INDEX(_xlpm.d,,11)="RS")),_xlpm.y,_xlfn.SORTBY(_xlpm.x,INDEX(_xlpm.x,,8),1,IF(INDEX(_xlpm.x,,9)="",1E+99,INDEX(_xlpm.x,,9)),-1,IF(INDEX(_xlpm.x,,10)="",0,INDEX(_xlpm.x,,10)),1),IFERROR(_xlfn.CHOOSECOLS(_xlfn.TAKE(_xlpm.y,1),8,9,10),""))} | Y6: {=_xlfn.LET(_xlpm.d,'페이백 미포함'!$A$2:$K$2061,_xlpm.p,_xlfn.XLOOKUP($B6,참조!$K$2:$K$30,IF(참조!$L$2:$L$30<>"",참조!$L$2:$L$30,참조!$M$2:$M$30),""),_xlpm.n,IF(OR($C6="SK",$C6="SKT"),"SKT",$C6),_xlpm.k,SUBSTITUTE(Y$3,"GB","G"),_xlpm.s,_xlfn.XLOOKUP(_xlpm.k,참조!$F$2:$F$15,참조!$B$2:$B$15,""),_xlpm.v,_xlfn.XLOOKUP(_xlpm.k,참조!$F$2:$F$15,참조!$D$2:$D$15,""),_xlpm.t,_xlfn.XLOOKUP(_xlpm.k,참조!$F$2:$F$15,참조!$E$2:$E$15,""),_xlpm.x,_xlfn._xlws.FILTER(_xlpm.d,(INDEX(_xlpm.d,,1)=_xlpm.p)*(INDEX(_xlpm.d,,3)=_xlpm.v)*(INDEX(_xlpm.d,,4)=_xlpm.t)*(INDEX(_xlpm.d,,5)=_xlpm.s)*(INDEX(_xlpm.d,,6)=_xlpm.n)*(INDEX(_xlpm.d,,11)="RS")),_xlpm.y,_xlfn.SORTBY(_xlpm.x,INDEX(_xlpm.x,,8),1,IF(INDEX(_xlpm.x,,9)="",1E+99,INDEX(_xlpm.x,,9)),-1,IF(INDEX(_xlpm.x,,10)="",0,INDEX(_xlpm.x,,10)),1),IFERROR(_xlfn.CHOOSECOLS(_xlfn.TAKE(_xlpm.y,1),8,9,10),""))}
B7: =B6 | C7: LG U+ | D7: {=_xlfn.LET(_xlpm.d,'페이백 미포함'!$A$2:$K$2061,_xlpm.p,_xlfn.XLOOKUP($B7,참조!$K$2:$K$30,IF(참조!$L$2:$L$30<>"",참조!$L$2:$L$30,참조!$M$2:$M$30),""),_xlpm.n,IF(OR($C7="SK",$C7="SKT"),"SKT",$C7),_xlpm.k,SUBSTITUTE(D$3,"GB","G"),_xlpm.s,_xlfn.XLOOKUP(_xlpm.k,참조!$F$2:$F$15,참조!$B$2:$B$15,""),_xlpm.v,_xlfn.XLOOKUP(_xlpm.k,참조!$F$2:$F$15,참조!$D$2:$D$15,""),_xlpm.t,_xlfn.XLOOKUP(_xlpm.k,참조!$F$2:$F$15,참조!$E$2:$E$15,""),_xlpm.x,_xlfn._xlws.FILTER(_xlpm.d,(INDEX(_xlpm.d,,1)=_xlpm.p)*(INDEX(_xlpm.d,,3)=_xlpm.v)*(INDEX(_xlpm.d,,4)=_xlpm.t)*(INDEX(_xlpm.d,,5)=_xlpm.s)*(INDEX(_xlpm.d,,6)=_xlpm.n)*(INDEX(_xlpm.d,,11)="RS")),_xlpm.y,_xlfn.SORTBY(_xlpm.x,INDEX(_xlpm.x,,8),1,IF(INDEX(_xlpm.x,,9)="",1E+99,INDEX(_xlpm.x,,9)),-1,IF(INDEX(_xlpm.x,,10)="",0,INDEX(_xlpm.x,,10)),1),IFERROR(_xlfn.CHOOSECOLS(_xlfn.TAKE(_xlpm.y,1),8,9,10),""))} | G7: {=_xlfn.LET(_xlpm.d,'페이백 미포함'!$A$2:$K$2061,_xlpm.p,_xlfn.XLOOKUP($B7,참조!$K$2:$K$30,IF(참조!$L$2:$L$30<>"",참조!$L$2:$L$30,참조!$M$2:$M$30),""),_xlpm.n,IF(OR($C7="SK",$C7="SKT"),"SKT",$C7),_xlpm.k,SUBSTITUTE(G$3,"GB","G"),_xlpm.s,_xlfn.XLOOKUP(_xlpm.k,참조!$F$2:$F$15,참조!$B$2:$B$15,""),_xlpm.v,_xlfn.XLOOKUP(_xlpm.k,참조!$F$2:$F$15,참조!$D$2:$D$15,""),_xlpm.t,_xlfn.XLOOKUP(_xlpm.k,참조!$F$2:$F$15,참조!$E$2:$E$15,""),_xlpm.x,_xlfn._xlws.FILTER(_xlpm.d,(INDEX(_xlpm.d,,1)=_xlpm.p)*(INDEX(_xlpm.d,,3)=_xlpm.v)*(INDEX(_xlpm.d,,4)=_xlpm.t)*(INDEX(_xlpm.d,,5)=_xlpm.s)*(INDEX(_xlpm.d,,6)=_xlpm.n)*(INDEX(_xlpm.d,,11)="RS")),_xlpm.y,_xlfn.SORTBY(_xlpm.x,INDEX(_xlpm.x,,8),1,IF(INDEX(_xlpm.x,,9)="",1E+99,INDEX(_xlpm.x,,9)),-1,IF(INDEX(_xlpm.x,,10)="",0,INDEX(_xlpm.x,,10)),1),IFERROR(_xlfn.CHOOSECOLS(_xlfn.TAKE(_xlpm.y,1),8,9,10),""))} | H7: 7 | I7: 33000 | J7: {=_xlfn.LET(_xlpm.d,'페이백 미포함'!$A$2:$K$2061,_xlpm.p,_xlfn.XLOOKUP($B7,참조!$K$2:$K$30,IF(참조!$L$2:$L$30<>"",참조!$L$2:$L$30,참조!$M$2:$M$30),""),_xlpm.n,IF(OR($C7="SK",$C7="SKT"),"SKT",$C7),_xlpm.k,SUBSTITUTE(J$3,"GB","G"),_xlpm.s,_xlfn.XLOOKUP(_xlpm.k,참조!$F$2:$F$15,참조!$B$2:$B$15,""),_xlpm.v,_xlfn.XLOOKUP(_xlpm.k,참조!$F$2:$F$15,참조!$D$2:$D$15,""),_xlpm.t,_xlfn.XLOOKUP(_xlpm.k,참조!$F$2:$F$15,참조!$E$2:$E$15,""),_xlpm.x,_xlfn._xlws.FILTER(_xlpm.d,(INDEX(_xlpm.d,,1)=_xlpm.p)*(INDEX(_xlpm.d,,3)=_xlpm.v)*(INDEX(_xlpm.d,,4)=_xlpm.t)*(INDEX(_xlpm.d,,5)=_xlpm.s)*(INDEX(_xlpm.d,,6)=_xlpm.n)*(INDEX(_xlpm.d,,11)="RS")),_xlpm.y,_xlfn.SORTBY(_xlpm.x,INDEX(_xlpm.x,,8),1,IF(INDEX(_xlpm.x,,9)="",1E+99,INDEX(_xlpm.x,,9)),-1,IF(INDEX(_xlpm.x,,10)="",0,INDEX(_xlpm.x,,10)),1),IFERROR(_xlfn.CHOOSECOLS(_xlfn.TAKE(_xlpm.y,1),8,9,10),""))} | K7: 24 | L7: 36300 | M7: {=_xlfn.LET(_xlpm.d,'페이백 미포함'!$A$2:$K$2061,_xlpm.p,_xlfn.XLOOKUP($B7,참조!$K$2:$K$30,IF(참조!$L$2:$L$30<>"",참조!$L$2:$L$30,참조!$M$2:$M$30),""),_xlpm.n,IF(OR($C7="SK",$C7="SKT"),"SKT",$C7),_xlpm.k,SUBSTITUTE(M$3,"GB","G"),_xlpm.s,_xlfn.XLOOKUP(_xlpm.k,참조!$F$2:$F$15,참조!$B$2:$B$15,""),_xlpm.v,_xlfn.XLOOKUP(_xlpm.k,참조!$F$2:$F$15,참조!$D$2:$D$15,""),_xlpm.t,_xlfn.XLOOKUP(_xlpm.k,참조!$F$2:$F$15,참조!$E$2:$E$15,""),_xlpm.x,_xlfn._xlws.FILTER(_xlpm.d,(INDEX(_xlpm.d,,1)=_xlpm.p)*(INDEX(_xlpm.d,,3)=_xlpm.v)*(INDEX(_xlpm.d,,4)=_xlpm.t)*(INDEX(_xlpm.d,,5)=_xlpm.s)*(INDEX(_xlpm.d,,6)=_xlpm.n)*(INDEX(_xlpm.d,,11)="RS")),_xlpm.y,_xlfn.SORTBY(_xlpm.x,INDEX(_xlpm.x,,8),1,IF(INDEX(_xlpm.x,,9)="",1E+99,INDEX(_xlpm.x,,9)),-1,IF(INDEX(_xlpm.x,,10)="",0,INDEX(_xlpm.x,,10)),1),IFERROR(_xlfn.CHOOSECOLS(_xlfn.TAKE(_xlpm.y,1),8,9,10),""))} | P7: {=_xlfn.LET(_xlpm.d,'페이백 미포함'!$A$2:$K$2061,_xlpm.p,_xlfn.XLOOKUP($B7,참조!$K$2:$K$30,IF(참조!$L$2:$L$30<>"",참조!$L$2:$L$30,참조!$M$2:$M$30),""),_xlpm.n,IF(OR($C7="SK",$C7="SKT"),"SKT",$C7),_xlpm.k,SUBSTITUTE(P$3,"GB","G"),_xlpm.s,_xlfn.XLOOKUP(_xlpm.k,참조!$F$2:$F$15,참조!$B$2:$B$15,""),_xlpm.v,_xlfn.XLOOKUP(_xlpm.k,참조!$F$2:$F$15,참조!$D$2:$D$15,""),_xlpm.t,_xlfn.XLOOKUP(_xlpm.k,참조!$F$2:$F$15,참조!$E$2:$E$15,""),_xlpm.x,_xlfn._xlws.FILTER(_xlpm.d,(INDEX(_xlpm.d,,1)=_xlpm.p)*(INDEX(_xlpm.d,,3)=_xlpm.v)*(INDEX(_xlpm.d,,4)=_xlpm.t)*(INDEX(_xlpm.d,,5)=_xlpm.s)*(INDEX(_xlpm.d,,6)=_xlpm.n)*(INDEX(_xlpm.d,,11)="RS")),_xlpm.y,_xlfn.SORTBY(_xlpm.x,INDEX(_xlpm.x,,8),1,IF(INDEX(_xlpm.x,,9)="",1E+99,INDEX(_xlpm.x,,9)),-1,IF(INDEX(_xlpm.x,,10)="",0,INDEX(_xlpm.x,,10)),1),IFERROR(_xlfn.CHOOSECOLS(_xlfn.TAKE(_xlpm.y,1),8,9,10),""))} | S7: {=_xlfn.LET(_xlpm.d,'페이백 미포함'!$A$2:$K$2061,_xlpm.p,_xlfn.XLOOKUP($B7,참조!$K$2:$K$30,IF(참조!$L$2:$L$30<>"",참조!$L$2:$L$30,참조!$M$2:$M$30),""),_xlpm.n,IF(OR($C7="SK",$C7="SKT"),"SKT",$C7),_xlpm.k,SUBSTITUTE(S$3,"GB","G"),_xlpm.s,_xlfn.XLOOKUP(_xlpm.k,참조!$F$2:$F$15,참조!$B$2:$B$15,""),_xlpm.v,_xlfn.XLOOKUP(_xlpm.k,참조!$F$2:$F$15,참조!$D$2:$D$15,""),_xlpm.t,_xlfn.XLOOKUP(_xlpm.k,참조!$F$2:$F$15,참조!$E$2:$E$15,""),_xlpm.x,_xlfn._xlws.FILTER(_xlpm.d,(INDEX(_xlpm.d,,1)=_xlpm.p)*(INDEX(_xlpm.d,,3)=_xlpm.v)*(INDEX(_xlpm.d,,4)=_xlpm.t)*(INDEX(_xlpm.d,,5)=_xlpm.s)*(INDEX(_xlpm.d,,6)=_xlpm.n)*(INDEX(_xlpm.d,,11)="RS")),_xlpm.y,_xlfn.SORTBY(_xlpm.x,INDEX(_xlpm.x,,8),1,IF(INDEX(_xlpm.x,,9)="",1E+99,INDEX(_xlpm.x,,9)),-1,IF(INDEX(_xlpm.x,,10)="",0,INDEX(_xlpm.x,,10)),1),IFERROR(_xlfn.CHOOSECOLS(_xlfn.TAKE(_xlpm.y,1),8,9,10),""))} | V7: {=_xlfn.LET(_xlpm.d,'페이백 미포함'!$A$2:$K$2061,_xlpm.p,_xlfn.XLOOKUP($B7,참조!$K$2:$K$30,IF(참조!$L$2:$L$30<>"",참조!$L$2:$L$30,참조!$M$2:$M$30),""),_xlpm.n,IF(OR($C7="SK",$C7="SKT"),"SKT",$C7),_xlpm.k,SUBSTITUTE(V$3,"GB","G"),_xlpm.s,_xlfn.XLOOKUP(_xlpm.k,참조!$F$2:$F$15,참조!$B$2:$B$15,""),_xlpm.v,_xlfn.XLOOKUP(_xlpm.k,참조!$F$2:$F$15,참조!$D$2:$D$15,""),_xlpm.t,_xlfn.XLOOKUP(_xlpm.k,참조!$F$2:$F$15,참조!$E$2:$E$15,""),_xlpm.x,_xlfn._xlws.FILTER(_xlpm.d,(INDEX(_xlpm.d,,1)=_xlpm.p)*(INDEX(_xlpm.d,,3)=_xlpm.v)*(INDEX(_xlpm.d,,4)=_xlpm.t)*(INDEX(_xlpm.d,,5)=_xlpm.s)*(INDEX(_xlpm.d,,6)=_xlpm.n)*(INDEX(_xlpm.d,,11)="RS")),_xlpm.y,_xlfn.SORTBY(_xlpm.x,INDEX(_xlpm.x,,8),1,IF(INDEX(_xlpm.x,,9)="",1E+99,INDEX(_xlpm.x,,9)),-1,IF(INDEX(_xlpm.x,,10)="",0,INDEX(_xlpm.x,,10)),1),IFERROR(_xlfn.CHOOSECOLS(_xlfn.TAKE(_xlpm.y,1),8,9,10),""))} | Y7: {=_xlfn.LET(_xlpm.d,'페이백 미포함'!$A$2:$K$2061,_xlpm.p,_xlfn.XLOOKUP($B7,참조!$K$2:$K$30,IF(참조!$L$2:$L$30<>"",참조!$L$2:$L$30,참조!$M$2:$M$30),""),_xlpm.n,IF(OR($C7="SK",$C7="SKT"),"SKT",$C7),_xlpm.k,SUBSTITUTE(Y$3,"GB","G"),_xlpm.s,_xlfn.XLOOKUP(_xlpm.k,참조!$F$2:$F$15,참조!$B$2:$B$15,""),_xlpm.v,_xlfn.XLOOKUP(_xlpm.k,참조!$F$2:$F$15,참조!$D$2:$D$15,""),_xlpm.t,_xlfn.XLOOKUP(_xlpm.k,참조!$F$2:$F$15,참조!$E$2:$E$15,""),_xlpm.x,_xlfn._xlws.FILTER(_xlpm.d,(INDEX(_xlpm.d,,1)=_xlpm.p)*(INDEX(_xlpm.d,,3)=_xlpm.v)*(INDEX(_xlpm.d,,4)=_xlpm.t)*(INDEX(_xlpm.d,,5)=_xlpm.s)*(INDEX(_xlpm.d,,6)=_xlpm.n)*(INDEX(_xlpm.d,,11)="RS")),_xlpm.y,_xlfn.SORTBY(_xlpm.x,INDEX(_xlpm.x,,8),1,IF(INDEX(_xlpm.x,,9)="",1E+99,INDEX(_xlpm.x,,9)),-1,IF(INDEX(_xlpm.x,,10)="",0,INDEX(_xlpm.x,,10)),1),IFERROR(_xlfn.CHOOSECOLS(_xlfn.TAKE(_xlpm.y,1),8,9,10),""))}
B8: 유니컴즈 | C8: SK | D8: {=_xlfn.LET(_xlpm.d,'페이백 미포함'!$A$2:$K$2061,_xlpm.p,_xlfn.XLOOKUP($B8,참조!$K$2:$K$30,IF(참조!$L$2:$L$30<>"",참조!$L$2:$L$30,참조!$M$2:$M$30),""),_xlpm.n,IF(OR($C8="SK",$C8="SKT"),"SKT",$C8),_xlpm.k,SUBSTITUTE(D$3,"GB","G"),_xlpm.s,_xlfn.XLOOKUP(_xlpm.k,참조!$F$2:$F$15,참조!$B$2:$B$15,""),_xlpm.v,_xlfn.XLOOKUP(_xlpm.k,참조!$F$2:$F$15,참조!$D$2:$D$15,""),_xlpm.t,_xlfn.XLOOKUP(_xlpm.k,참조!$F$2:$F$15,참조!$E$2:$E$15,""),_xlpm.x,_xlfn._xlws.FILTER(_xlpm.d,(INDEX(_xlpm.d,,1)=_xlpm.p)*(INDEX(_xlpm.d,,3)=_xlpm.v)*(INDEX(_xlpm.d,,4)=_xlpm.t)*(INDEX(_xlpm.d,,5)=_xlpm.s)*(INDEX(_xlpm.d,,6)=_xlpm.n)*(INDEX(_xlpm.d,,11)="RS")),_xlpm.y,_xlfn.SORTBY(_xlpm.x,INDEX(_xlpm.x,,8),1,IF(INDEX(_xlpm.x,,9)="",1E+99,INDEX(_xlpm.x,,9)),-1,IF(INDEX(_xlpm.x,,10)="",0,INDEX(_xlpm.x,,10)),1),IFERROR(_xlfn.CHOOSECOLS(_xlfn.TAKE(_xlpm.y,1),8,9,10),""))} | E8: 7 | F8: 26400 | G8: {=_xlfn.LET(_xlpm.d,'페이백 미포함'!$A$2:$K$2061,_xlpm.p,_xlfn.XLOOKUP($B8,참조!$K$2:$K$30,IF(참조!$L$2:$L$30<>"",참조!$L$2:$L$30,참조!$M$2:$M$30),""),_xlpm.n,IF(OR($C8="SK",$C8="SKT"),"SKT",$C8),_xlpm.k,SUBSTITUTE(G$3,"GB","G"),_xlpm.s,_xlfn.XLOOKUP(_xlpm.k,참조!$F$2:$F$15,참조!$B$2:$B$15,""),_xlpm.v,_xlfn.XLOOKUP(_xlpm.k,참조!$F$2:$F$15,참조!$D$2:$D$15,""),_xlpm.t,_xlfn.XLOOKUP(_xlpm.k,참조!$F$2:$F$15,참조!$E$2:$E$15,""),_xlpm.x,_xlfn._xlws.FILTER(_xlpm.d,(INDEX(_xlpm.d,,1)=_xlpm.p)*(INDEX(_xlpm.d,,3)=_xlpm.v)*(INDEX(_xlpm.d,,4)=_xlpm.t)*(INDEX(_xlpm.d,,5)=_xlpm.s)*(INDEX(_xlpm.d,,6)=_xlpm.n)*(INDEX(_xlpm.d,,11)="RS")),_xlpm.y,_xlfn.SORTBY(_xlpm.x,INDEX(_xlpm.x,,8),1,IF(INDEX(_xlpm.x,,9)="",1E+99,INDEX(_xlpm.x,,9)),-1,IF(INDEX(_xlpm.x,,10)="",0,INDEX(_xlpm.x,,10)),1),IFERROR(_xlfn.CHOOSECOLS(_xlfn.TAKE(_xlpm.y,1),8,9,10),""))} | H8: 7 | I8: 36300 | J8: {=_xlfn.LET(_xlpm.d,'페이백 미포함'!$A$2:$K$2061,_xlpm.p,_xlfn.XLOOKUP($B8,참조!$K$2:$K$30,IF(참조!$L$2:$L$30<>"",참조!$L$2:$L$30,참조!$M$2:$M$30),""),_xlpm.n,IF(OR($C8="SK",$C8="SKT"),"SKT",$C8),_xlpm.k,SUBSTITUTE(J$3,"GB","G"),_xlpm.s,_xlfn.XLOOKUP(_xlpm.k,참조!$F$2:$F$15,참조!$B$2:$B$15,""),_xlpm.v,_xlfn.XLOOKUP(_xlpm.k,참조!$F$2:$F$15,참조!$D$2:$D$15,""),_xlpm.t,_xlfn.XLOOKUP(_xlpm.k,참조!$F$2:$F$15,참조!$E$2:$E$15,""),_xlpm.x,_xlfn._xlws.FILTER(_xlpm.d,(INDEX(_xlpm.d,,1)=_xlpm.p)*(INDEX(_xlpm.d,,3)=_xlpm.v)*(INDEX(_xlpm.d,,4)=_xlpm.t)*(INDEX(_xlpm.d,,5)=_xlpm.s)*(INDEX(_xlpm.d,,6)=_xlpm.n)*(INDEX(_xlpm.d,,11)="RS")),_xlpm.y,_xlfn.SORTBY(_xlpm.x,INDEX(_xlpm.x,,8),1,IF(INDEX(_xlpm.x,,9)="",1E+99,INDEX(_xlpm.x,,9)),-1,IF(INDEX(_xlpm.x,,10)="",0,INDEX(_xlpm.x,,10)),1),IFERROR(_xlfn.CHOOSECOLS(_xlfn.TAKE(_xlpm.y,1),8,9,10),""))} | K8: 7 | L8: 40700 | M8: {=_xlfn.LET(_xlpm.d,'페이백 미포함'!$A$2:$K$2061,_xlpm.p,_xlfn.XLOOKUP($B8,참조!$K$2:$K$30,IF(참조!$L$2:$L$30<>"",참조!$L$2:$L$30,참조!$M$2:$M$30),""),_xlpm.n,IF(OR($C8="SK",$C8="SKT"),"SKT",$C8),_xlpm.k,SUBSTITUTE(M$3,"GB","G"),_xlpm.s,_xlfn.XLOOKUP(_xlpm.k,참조!$F$2:$F$15,참조!$B$2:$B$15,""),_xlpm.v,_xlfn.XLOOKUP(_xlpm.k,참조!$F$2:$F$15,참조!$D$2:$D$15,""),_xlpm.t,_xlfn.XLOOKUP(_xlpm.k,참조!$F$2:$F$15,참조!$E$2:$E$15,""),_xlpm.x,_xlfn._xlws.FILTER(_xlpm.d,(INDEX(_xlpm.d,,1)=_xlpm.p)*(INDEX(_xlpm.d,,3)=_xlpm.v)*(INDEX(_xlpm.d,,4)=_xlpm.t)*(INDEX(_xlpm.d,,5)=_xlpm.s)*(INDEX(_xlpm.d,,6)=_xlpm.n)*(INDEX(_xlpm.d,,11)="RS")),_xlpm.y,_xlfn.SORTBY(_xlpm.x,INDEX(_xlpm.x,,8),1,IF(INDEX(_xlpm.x,,9)="",1E+99,INDEX(_xlpm.x,,9)),-1,IF(INDEX(_xlpm.x,,10)="",0,INDEX(_xlpm.x,,10)),1),IFERROR(_xlfn.CHOOSECOLS(_xlfn.TAKE(_xlpm.y,1),8,9,10),""))} | N8: 7 | O8: 46200 | P8: {=_xlfn.LET(_xlpm.d,'페이백 미포함'!$A$2:$K$2061,_xlpm.p,_xlfn.XLOOKUP($B8,참조!$K$2:$K$30,IF(참조!$L$2:$L$30<>"",참조!$L$2:$L$30,참조!$M$2:$M$30),""),_xlpm.n,IF(OR($C8="SK",$C8="SKT"),"SKT",$C8),_xlpm.k,SUBSTITUTE(P$3,"GB","G"),_xlpm.s,_xlfn.XLOOKUP(_xlpm.k,참조!$F$2:$F$15,참조!$B$2:$B$15,""),_xlpm.v,_xlfn.XLOOKUP(_xlpm.k,참조!$F$2:$F$15,참조!$D$2:$D$15,""),_xlpm.t,_xlfn.XLOOKUP(_xlpm.k,참조!$F$2:$F$15,참조!$E$2:$E$15,""),_xlpm.x,_xlfn._xlws.FILTER(_xlpm.d,(INDEX(_xlpm.d,,1)=_xlpm.p)*(INDEX(_xlpm.d,,3)=_xlpm.v)*(INDEX(_xlpm.d,,4)=_xlpm.t)*(INDEX(_xlpm.d,,5)=_xlpm.s)*(INDEX(_xlpm.d,,6)=_xlpm.n)*(INDEX(_xlpm.d,,11)="RS")),_xlpm.y,_xlfn.SORTBY(_xlpm.x,INDEX(_xlpm.x,,8),1,IF(INDEX(_xlpm.x,,9)="",1E+99,INDEX(_xlpm.x,,9)),-1,IF(INDEX(_xlpm.x,,10)="",0,INDEX(_xlpm.x,,10)),1),IFERROR(_xlfn.CHOOSECOLS(_xlfn.TAKE(_xlpm.y,1),8,9,10),""))} | Q8: 7 | R8: 53900 | S8: {=_xlfn.LET(_xlpm.d,'페이백 미포함'!$A$2:$K$2061,_xlpm.p,_xlfn.XLOOKUP($B8,참조!$K$2:$K$30,IF(참조!$L$2:$L$30<>"",참조!$L$2:$L$30,참조!$M$2:$M$30),""),_xlpm.n,IF(OR($C8="SK",$C8="SKT"),"SKT",$C8),_xlpm.k,SUBSTITUTE(S$3,"GB","G"),_xlpm.s,_xlfn.XLOOKUP(_xlpm.k,참조!$F$2:$F$15,참조!$B$2:$B$15,""),_xlpm.v,_xlfn.XLOOKUP(_xlpm.k,참조!$F$2:$F$15,참조!$D$2:$D$15,""),_xlpm.t,_xlfn.XLOOKUP(_xlpm.k,참조!$F$2:$F$15,참조!$E$2:$E$15,""),_xlpm.x,_xlfn._xlws.FILTER(_xlpm.d,(INDEX(_xlpm.d,,1)=_xlpm.p)*(INDEX(_xlpm.d,,3)=_xlpm.v)*(INDEX(_xlpm.d,,4)=_xlpm.t)*(INDEX(_xlpm.d,,5)=_xlpm.s)*(INDEX(_xlpm.d,,6)=_xlpm.n)*(INDEX(_xlpm.d,,11)="RS")),_xlpm.y,_xlfn.SORTBY(_xlpm.x,INDEX(_xlpm.x,,8),1,IF(INDEX(_xlpm.x,,9)="",1E+99,INDEX(_xlpm.x,,9)),-1,IF(INDEX(_xlpm.x,,10)="",0,INDEX(_xlpm.x,,10)),1),IFERROR(_xlfn.CHOOSECOLS(_xlfn.TAKE(_xlpm.y,1),8,9,10),""))} | V8: {=_xlfn.LET(_xlpm.d,'페이백 미포함'!$A$2:$K$2061,_xlpm.p,_xlfn.XLOOKUP($B8,참조!$K$2:$K$30,IF(참조!$L$2:$L$30<>"",참조!$L$2:$L$30,참조!$M$2:$M$30),""),_xlpm.n,IF(OR($C8="SK",$C8="SKT"),"SKT",$C8),_xlpm.k,SUBSTITUTE(V$3,"GB","G"),_xlpm.s,_xlfn.XLOOKUP(_xlpm.k,참조!$F$2:$F$15,참조!$B$2:$B$15,""),_xlpm.v,_xlfn.XLOOKUP(_xlpm.k,참조!$F$2:$F$15,참조!$D$2:$D$15,""),_xlpm.t,_xlfn.XLOOKUP(_xlpm.k,참조!$F$2:$F$15,참조!$E$2:$E$15,""),_xlpm.x,_xlfn._xlws.FILTER(_xlpm.d,(INDEX(_xlpm.d,,1)=_xlpm.p)*(INDEX(_xlpm.d,,3)=_xlpm.v)*(INDEX(_xlpm.d,,4)=_xlpm.t)*(INDEX(_xlpm.d,,5)=_xlpm.s)*(INDEX(_xlpm.d,,6)=_xlpm.n)*(INDEX(_xlpm.d,,11)="RS")),_xlpm.y,_xlfn.SORTBY(_xlpm.x,INDEX(_xlpm.x,,8),1,IF(INDEX(_xlpm.x,,9)="",1E+99,INDEX(_xlpm.x,,9)),-1,IF(INDEX(_xlpm.x,,10)="",0,INDEX(_xlpm.x,,10)),1),IFERROR(_xlfn.CHOOSECOLS(_xlfn.TAKE(_xlpm.y,1),8,9,10),""))} | Y8: {=_xlfn.LET(_xlpm.d,'페이백 미포함'!$A$2:$K$2061,_xlpm.p,_xlfn.XLOOKUP($B8,참조!$K$2:$K$30,IF(참조!$L$2:$L$30<>"",참조!$L$2:$L$30,참조!$M$2:$M$30),""),_xlpm.n,IF(OR($C8="SK",$C8="SKT"),"SKT",$C8),_xlpm.k,SUBSTITUTE(Y$3,"GB","G"),_xlpm.s,_xlfn.XLOOKUP(_xlpm.k,참조!$F$2:$F$15,참조!$B$2:$B$15,""),_xlpm.v,_xlfn.XLOOKUP(_xlpm.k,참조!$F$2:$F$15,참조!$D$2:$D$15,""),_xlpm.t,_xlfn.XLOOKUP(_xlpm.k,참조!$F$2:$F$15,참조!$E$2:$E$15,""),_xlpm.x,_xlfn._xlws.FILTER(_xlpm.d,(INDEX(_xlpm.d,,1)=_xlpm.p)*(INDEX(_xlpm.d,,3)=_xlpm.v)*(INDEX(_xlpm.d,,4)=_xlpm.t)*(INDEX(_xlpm.d,,5)=_xlpm.s)*(INDEX(_xlpm.d,,6)=_xlpm.n)*(INDEX(_xlpm.d,,11)="RS")),_xlpm.y,_xlfn.SORTBY(_xlpm.x,INDEX(_xlpm.x,,8),1,IF(INDEX(_xlpm.x,,9)="",1E+99,INDEX(_xlpm.x,,9)),-1,IF(INDEX(_xlpm.x,,10)="",0,INDEX(_xlpm.x,,10)),1),IFERROR(_xlfn.CHOOSECOLS(_xlfn.TAKE(_xlpm.y,1),8,9,10),""))}
B9: =B8 | C9: KT | D9: {=_xlfn.LET(_xlpm.d,'페이백 미포함'!$A$2:$K$2061,_xlpm.p,_xlfn.XLOOKUP($B9,참조!$K$2:$K$30,IF(참조!$L$2:$L$30<>"",참조!$L$2:$L$30,참조!$M$2:$M$30),""),_xlpm.n,IF(OR($C9="SK",$C9="SKT"),"SKT",$C9),_xlpm.k,SUBSTITUTE(D$3,"GB","G"),_xlpm.s,_xlfn.XLOOKUP(_xlpm.k,참조!$F$2:$F$15,참조!$B$2:$B$15,""),_xlpm.v,_xlfn.XLOOKUP(_xlpm.k,참조!$F$2:$F$15,참조!$D$2:$D$15,""),_xlpm.t,_xlfn.XLOOKUP(_xlpm.k,참조!$F$2:$F$15,참조!$E$2:$E$15,""),_xlpm.x,_xlfn._xlws.FILTER(_xlpm.d,(INDEX(_xlpm.d,,1)=_xlpm.p)*(INDEX(_xlpm.d,,3)=_xlpm.v)*(INDEX(_xlpm.d,,4)=_xlpm.t)*(INDEX(_xlpm.d,,5)=_xlpm.s)*(INDEX(_xlpm.d,,6)=_xlpm.n)*(INDEX(_xlpm.d,,11)="RS")),_xlpm.y,_xlfn.SORTBY(_xlpm.x,INDEX(_xlpm.x,,8),1,IF(INDEX(_xlpm.x,,9)="",1E+99,INDEX(_xlpm.x,,9)),-1,IF(INDEX(_xlpm.x,,10)="",0,INDEX(_xlpm.x,,10)),1),IFERROR(_xlfn.CHOOSECOLS(_xlfn.TAKE(_xlpm.y,1),8,9,10),""))} | E9: 7 | F9: 26400 | G9: {=_xlfn.LET(_xlpm.d,'페이백 미포함'!$A$2:$K$2061,_xlpm.p,_xlfn.XLOOKUP($B9,참조!$K$2:$K$30,IF(참조!$L$2:$L$30<>"",참조!$L$2:$L$30,참조!$M$2:$M$30),""),_xlpm.n,IF(OR($C9="SK",$C9="SKT"),"SKT",$C9),_xlpm.k,SUBSTITUTE(G$3,"GB","G"),_xlpm.s,_xlfn.XLOOKUP(_xlpm.k,참조!$F$2:$F$15,참조!$B$2:$B$15,""),_xlpm.v,_xlfn.XLOOKUP(_xlpm.k,참조!$F$2:$F$15,참조!$D$2:$D$15,""),_xlpm.t,_xlfn.XLOOKUP(_xlpm.k,참조!$F$2:$F$15,참조!$E$2:$E$15,""),_xlpm.x,_xlfn._xlws.FILTER(_xlpm.d,(INDEX(_xlpm.d,,1)=_xlpm.p)*(INDEX(_xlpm.d,,3)=_xlpm.v)*(INDEX(_xlpm.d,,4)=_xlpm.t)*(INDEX(_xlpm.d,,5)=_xlpm.s)*(INDEX(_xlpm.d,,6)=_xlpm.n)*(INDEX(_xlpm.d,,11)="RS")),_xlpm.y,_xlfn.SORTBY(_xlpm.x,INDEX(_xlpm.x,,8),1,IF(INDEX(_xlpm.x,,9)="",1E+99,INDEX(_xlpm.x,,9)),-1,IF(INDEX(_xlpm.x,,10)="",0,INDEX(_xlpm.x,,10)),1),IFERROR(_xlfn.CHOOSECOLS(_xlfn.TAKE(_xlpm.y,1),8,9,10),""))} | H9: 7 | I9: 37400 | J9: {=_xlfn.LET(_xlpm.d,'페이백 미포함'!$A$2:$K$2061,_xlpm.p,_xlfn.XLOOKUP($B9,참조!$K$2:$K$30,IF(참조!$L$2:$L$30<>"",참조!$L$2:$L$30,참조!$M$2:$M$30),""),_xlpm.n,IF(OR($C9="SK",$C9="SKT"),"SKT",$C9),_xlpm.k,SUBSTITUTE(J$3,"GB","G"),_xlpm.s,_xlfn.XLOOKUP(_xlpm.k,참조!$F$2:$F$15,참조!$B$2:$B$15,""),_xlpm.v,_xlfn.XLOOKUP(_xlpm.k,참조!$F$2:$F$15,참조!$D$2:$D$15,""),_xlpm.t,_xlfn.XLOOKUP(_xlpm.k,참조!$F$2:$F$15,참조!$E$2:$E$15,""),_xlpm.x,_xlfn._xlws.FILTER(_xlpm.d,(INDEX(_xlpm.d,,1)=_xlpm.p)*(INDEX(_xlpm.d,,3)=_xlpm.v)*(INDEX(_xlpm.d,,4)=_xlpm.t)*(INDEX(_xlpm.d,,5)=_xlpm.s)*(INDEX(_xlpm.d,,6)=_xlpm.n)*(INDEX(_xlpm.d,,11)="RS")),_xlpm.y,_xlfn.SORTBY(_xlpm.x,INDEX(_xlpm.x,,8),1,IF(INDEX(_xlpm.x,,9)="",1E+99,INDEX(_xlpm.x,,9)),-1,IF(INDEX(_xlpm.x,,10)="",0,INDEX(_xlpm.x,,10)),1),IFERROR(_xlfn.CHOOSECOLS(_xlfn.TAKE(_xlpm.y,1),8,9,10),""))} | K9: 7 | L9: 45100 | M9: {=_xlfn.LET(_xlpm.d,'페이백 미포함'!$A$2:$K$2061,_xlpm.p,_xlfn.XLOOKUP($B9,참조!$K$2:$K$30,IF(참조!$L$2:$L$30<>"",참조!$L$2:$L$30,참조!$M$2:$M$30),""),_xlpm.n,IF(OR($C9="SK",$C9="SKT"),"SKT",$C9),_xlpm.k,SUBSTITUTE(M$3,"GB","G"),_xlpm.s,_xlfn.XLOOKUP(_xlpm.k,참조!$F$2:$F$15,참조!$B$2:$B$15,""),_xlpm.v,_xlfn.XLOOKUP(_xlpm.k,참조!$F$2:$F$15,참조!$D$2:$D$15,""),_xlpm.t,_xlfn.XLOOKUP(_xlpm.k,참조!$F$2:$F$15,참조!$E$2:$E$15,""),_xlpm.x,_xlfn._xlws.FILTER(_xlpm.d,(INDEX(_xlpm.d,,1)=_xlpm.p)*(INDEX(_xlpm.d,,3)=_xlpm.v)*(INDEX(_xlpm.d,,4)=_xlpm.t)*(INDEX(_xlpm.d,,5)=_xlpm.s)*(INDEX(_xlpm.d,,6)=_xlpm.n)*(INDEX(_xlpm.d,,11)="RS")),_xlpm.y,_xlfn.SORTBY(_xlpm.x,INDEX(_xlpm.x,,8),1,IF(INDEX(_xlpm.x,,9)="",1E+99,INDEX(_xlpm.x,,9)),-1,IF(INDEX(_xlpm.x,,10)="",0,INDEX(_xlpm.x,,10)),1),IFERROR(_xlfn.CHOOSECOLS(_xlfn.TAKE(_xlpm.y,1),8,9,10),""))} | N9: 7 | O9: 48400 | P9: {=_xlfn.LET(_xlpm.d,'페이백 미포함'!$A$2:$K$2061,_xlpm.p,_xlfn.XLOOKUP($B9,참조!$K$2:$K$30,IF(참조!$L$2:$L$30<>"",참조!$L$2:$L$30,참조!$M$2:$M$30),""),_xlpm.n,IF(OR($C9="SK",$C9="SKT"),"SKT",$C9),_xlpm.k,SUBSTITUTE(P$3,"GB","G"),_xlpm.s,_xlfn.XLOOKUP(_xlpm.k,참조!$F$2:$F$15,참조!$B$2:$B$15,""),_xlpm.v,_xlfn.XLOOKUP(_xlpm.k,참조!$F$2:$F$15,참조!$D$2:$D$15,""),_xlpm.t,_xlfn.XLOOKUP(_xlpm.k,참조!$F$2:$F$15,참조!$E$2:$E$15,""),_xlpm.x,_xlfn._xlws.FILTER(_xlpm.d,(INDEX(_xlpm.d,,1)=_xlpm.p)*(INDEX(_xlpm.d,,3)=_xlpm.v)*(INDEX(_xlpm.d,,4)=_xlpm.t)*(INDEX(_xlpm.d,,5)=_xlpm.s)*(INDEX(_xlpm.d,,6)=_xlpm.n)*(INDEX(_xlpm.d,,11)="RS")),_xlpm.y,_xlfn.SORTBY(_xlpm.x,INDEX(_xlpm.x,,8),1,IF(INDEX(_xlpm.x,,9)="",1E+99,INDEX(_xlpm.x,,9)),-1,IF(INDEX(_xlpm.x,,10)="",0,INDEX(_xlpm.x,,10)),1),IFERROR(_xlfn.CHOOSECOLS(_xlfn.TAKE(_xlpm.y,1),8,9,10),""))} | Q9: 7 | R9: 50600 | S9: {=_xlfn.LET(_xlpm.d,'페이백 미포함'!$A$2:$K$2061,_xlpm.p,_xlfn.XLOOKUP($B9,참조!$K$2:$K$30,IF(참조!$L$2:$L$30<>"",참조!$L$2:$L$30,참조!$M$2:$M$30),""),_xlpm.n,IF(OR($C9="SK",$C9="SKT"),"SKT",$C9),_xlpm.k,SUBSTITUTE(S$3,"GB","G"),_xlpm.s,_xlfn.XLOOKUP(_xlpm.k,참조!$F$2:$F$15,참조!$B$2:$B$15,""),_xlpm.v,_xlfn.XLOOKUP(_xlpm.k,참조!$F$2:$F$15,참조!$D$2:$D$15,""),_xlpm.t,_xlfn.XLOOKUP(_xlpm.k,참조!$F$2:$F$15,참조!$E$2:$E$15,""),_xlpm.x,_xlfn._xlws.FILTER(_xlpm.d,(INDEX(_xlpm.d,,1)=_xlpm.p)*(INDEX(_xlpm.d,,3)=_xlpm.v)*(INDEX(_xlpm.d,,4)=_xlpm.t)*(INDEX(_xlpm.d,,5)=_xlpm.s)*(INDEX(_xlpm.d,,6)=_xlpm.n)*(INDEX(_xlpm.d,,11)="RS")),_xlpm.y,_xlfn.SORTBY(_xlpm.x,INDEX(_xlpm.x,,8),1,IF(INDEX(_xlpm.x,,9)="",1E+99,INDEX(_xlpm.x,,9)),-1,IF(INDEX(_xlpm.x,,10)="",0,INDEX(_xlpm.x,,10)),1),IFERROR(_xlfn.CHOOSECOLS(_xlfn.TAKE(_xlpm.y,1),8,9,10),""))} | V9: {=_xlfn.LET(_xlpm.d,'페이백 미포함'!$A$2:$K$2061,_xlpm.p,_xlfn.XLOOKUP($B9,참조!$K$2:$K$30,IF(참조!$L$2:$L$30<>"",참조!$L$2:$L$30,참조!$M$2:$M$30),""),_xlpm.n,IF(OR($C9="SK",$C9="SKT"),"SKT",$C9),_xlpm.k,SUBSTITUTE(V$3,"GB","G"),_xlpm.s,_xlfn.XLOOKUP(_xlpm.k,참조!$F$2:$F$15,참조!$B$2:$B$15,""),_xlpm.v,_xlfn.XLOOKUP(_xlpm.k,참조!$F$2:$F$15,참조!$D$2:$D$15,""),_xlpm.t,_xlfn.XLOOKUP(_xlpm.k,참조!$F$2:$F$15,참조!$E$2:$E$15,""),_xlpm.x,_xlfn._xlws.FILTER(_xlpm.d,(INDEX(_xlpm.d,,1)=_xlpm.p)*(INDEX(_xlpm.d,,3)=_xlpm.v)*(INDEX(_xlpm.d,,4)=_xlpm.t)*(INDEX(_xlpm.d,,5)=_xlpm.s)*(INDEX(_xlpm.d,,6)=_xlpm.n)*(INDEX(_xlpm.d,,11)="RS")),_xlpm.y,_xlfn.SORTBY(_xlpm.x,INDEX(_xlpm.x,,8),1,IF(INDEX(_xlpm.x,,9)="",1E+99,INDEX(_xlpm.x,,9)),-1,IF(INDEX(_xlpm.x,,10)="",0,INDEX(_xlpm.x,,10)),1),IFERROR(_xlfn.CHOOSECOLS(_xlfn.TAKE(_xlpm.y,1),8,9,10),""))} | Y9: {=_xlfn.LET(_xlpm.d,'페이백 미포함'!$A$2:$K$2061,_xlpm.p,_xlfn.XLOOKUP($B9,참조!$K$2:$K$30,IF(참조!$L$2:$L$30<>"",참조!$L$2:$L$30,참조!$M$2:$M$30),""),_xlpm.n,IF(OR($C9="SK",$C9="SKT"),"SKT",$C9),_xlpm.k,SUBSTITUTE(Y$3,"GB","G"),_xlpm.s,_xlfn.XLOOKUP(_xlpm.k,참조!$F$2:$F$15,참조!$B$2:$B$15,""),_xlpm.v,_xlfn.XLOOKUP(_xlpm.k,참조!$F$2:$F$15,참조!$D$2:$D$15,""),_xlpm.t,_xlfn.XLOOKUP(_xlpm.k,참조!$F$2:$F$15,참조!$E$2:$E$15,""),_xlpm.x,_xlfn._xlws.FILTER(_xlpm.d,(INDEX(_xlpm.d,,1)=_xlpm.p)*(INDEX(_xlpm.d,,3)=_xlpm.v)*(INDEX(_xlpm.d,,4)=_xlpm.t)*(INDEX(_xlpm.d,,5)=_xlpm.s)*(INDEX(_xlpm.d,,6)=_xlpm.n)*(INDEX(_xlpm.d,,11)="RS")),_xlpm.y,_xlfn.SORTBY(_xlpm.x,INDEX(_xlpm.x,,8),1,IF(INDEX(_xlpm.x,,9)="",1E+99,INDEX(_xlpm.x,,9)),-1,IF(INDEX(_xlpm.x,,10)="",0,INDEX(_xlpm.x,,10)),1),IFERROR(_xlfn.CHOOSECOLS(_xlfn.TAKE(_xlpm.y,1),8,9,10),""))}
